[Tue Dec 29 20:37:08.359004 2020] [proxy_fcgi:error] [pid 752717:tid 140152282240768] [client 51.210.97.29:56513] AH01071: Got error 'Primary script unknown', referer: http://www.g11.labagh.pl/wp-login.php
[Fri Jan 01 03:05:44.169662 2021] [proxy_fcgi:error] [pid 803830:tid 140376904034048] [client 62.210.185.4:50462] AH01071: Got error 'Primary script unknown', referer: http://g11.labagh.pl/wp-login.php
[Sat Jan 02 18:39:02.974056 2021] [wsgi:error] [pid 948350:tid 140214513559296] [remote 185.213.154.164:50574] Not Found: /favicon.ico
[Sat Jan 02 18:39:08.077384 2021] [wsgi:error] [pid 948350:tid 140214513559296] [remote 52.114.75.71:54336] Not Found: /favicon.ico
Exception ignored in: <bound method BaseEventLoop.__del__ of <_UnixSelectorEventLoop running=False closed=False debug=False>>
Traceback (most recent call last):
  File "/usr/lib64/python3.6/asyncio/base_events.py", line 526, in __del__
NameError: name 'ResourceWarning' is not defined
[Sat Jan 02 19:59:15.820911 2021] [wsgi:error] [pid 952099:tid 140214572308224] [remote 89.64.42.253:30352] Not Found: /
Exception ignored in: <bound method BaseEventLoop.__del__ of <_UnixSelectorEventLoop running=False closed=False debug=False>>
Traceback (most recent call last):
  File "/usr/lib64/python3.6/asyncio/base_events.py", line 526, in __del__
NameError: name 'ResourceWarning' is not defined
[Sat Jan 02 20:00:49.853461 2021] [wsgi:error] [pid 952190:tid 140214572308224] [remote 89.64.42.253:30328] Not Found: /
[Sat Jan 02 20:03:39.295338 2021] [wsgi:error] [pid 952190:tid 140214555522816] [remote 89.64.42.253:30206] Not Found: /
[Sat Jan 02 20:09:38.630071 2021] [wsgi:error] [pid 952190:tid 140214572308224] [remote 89.64.42.253:20504] Not Found: /
[Sat Jan 02 20:18:28.781656 2021] [wsgi:error] [pid 952190:tid 140214572308224] [remote 89.64.42.253:30262] Not Found: /
[Sat Jan 02 20:18:29.875051 2021] [wsgi:error] [pid 952190:tid 140214555522816] [remote 89.64.42.253:30231] Not Found: /
[Sat Jan 02 20:23:03.682775 2021] [wsgi:error] [pid 952190:tid 140214572308224] [remote 195.136.137.175:60520] Not Found: /
[Sat Jan 02 20:23:03.827944 2021] [wsgi:error] [pid 952190:tid 140214555522816] [remote 195.136.137.175:60520] Not Found: /favicon.ico
[Sat Jan 02 21:45:04.998285 2021] [wsgi:error] [pid 952190:tid 140214572308224] [remote 89.64.42.253:30321] Not Found: /
[Sat Jan 02 22:31:29.717787 2021] [wsgi:error] [pid 952190:tid 140214572308224] [remote 89.64.42.253:30205] Not Found: /
[Sat Jan 02 23:44:43.598725 2021] [wsgi:error] [pid 952190:tid 140214555522816] [remote 37.47.125.67:2963] Not Found: /
[Sat Jan 02 23:44:44.204100 2021] [wsgi:error] [pid 952190:tid 140214572308224] [remote 37.47.125.67:25576] Not Found: /favicon.ico
Exception ignored in: <bound method BaseEventLoop.__del__ of <_UnixSelectorEventLoop running=False closed=False debug=False>>
Traceback (most recent call last):
  File "/usr/lib64/python3.6/asyncio/base_events.py", line 526, in __del__
NameError: name 'ResourceWarning' is not defined
[Sun Jan 03 10:57:15.405944 2021] [wsgi:error] [pid 968358:tid 140214572308224] [remote 188.147.40.42:31170] Not Found: /favicon.ico
[Sun Jan 03 10:57:20.201191 2021] [wsgi:error] [pid 968358:tid 140214454810368] [remote 188.147.40.42:31170] Not Found: /
[Sun Jan 03 10:57:47.365616 2021] [wsgi:error] [pid 968358:tid 140214454810368] [remote 188.147.40.42:30979] Internal Server Error: /admin/login/
[Sun Jan 03 10:57:47.365709 2021] [wsgi:error] [pid 968358:tid 140214454810368] [remote 188.147.40.42:30979] Traceback (most recent call last):
[Sun Jan 03 10:57:47.365714 2021] [wsgi:error] [pid 968358:tid 140214454810368] [remote 188.147.40.42:30979]   File "/usr/local/lib/python3.6/site-packages/django/db/backends/utils.py", line 84, in _execute
[Sun Jan 03 10:57:47.365719 2021] [wsgi:error] [pid 968358:tid 140214454810368] [remote 188.147.40.42:30979]     return self.cursor.execute(sql, params)
[Sun Jan 03 10:57:47.365723 2021] [wsgi:error] [pid 968358:tid 140214454810368] [remote 188.147.40.42:30979]   File "/usr/local/lib/python3.6/site-packages/django/db/backends/sqlite3/base.py", line 413, in execute
[Sun Jan 03 10:57:47.365749 2021] [wsgi:error] [pid 968358:tid 140214454810368] [remote 188.147.40.42:30979]     return Database.Cursor.execute(self, query, params)
[Sun Jan 03 10:57:47.365752 2021] [wsgi:error] [pid 968358:tid 140214454810368] [remote 188.147.40.42:30979] sqlite3.OperationalError: no such table: auth_user
[Sun Jan 03 10:57:47.365756 2021] [wsgi:error] [pid 968358:tid 140214454810368] [remote 188.147.40.42:30979] 
[Sun Jan 03 10:57:47.365759 2021] [wsgi:error] [pid 968358:tid 140214454810368] [remote 188.147.40.42:30979] The above exception was the direct cause of the following exception:
[Sun Jan 03 10:57:47.365763 2021] [wsgi:error] [pid 968358:tid 140214454810368] [remote 188.147.40.42:30979] 
[Sun Jan 03 10:57:47.365766 2021] [wsgi:error] [pid 968358:tid 140214454810368] [remote 188.147.40.42:30979] Traceback (most recent call last):
[Sun Jan 03 10:57:47.365769 2021] [wsgi:error] [pid 968358:tid 140214454810368] [remote 188.147.40.42:30979]   File "/usr/local/lib/python3.6/site-packages/django/core/handlers/exception.py", line 47, in inner
[Sun Jan 03 10:57:47.365773 2021] [wsgi:error] [pid 968358:tid 140214454810368] [remote 188.147.40.42:30979]     response = get_response(request)
[Sun Jan 03 10:57:47.365776 2021] [wsgi:error] [pid 968358:tid 140214454810368] [remote 188.147.40.42:30979]   File "/usr/local/lib/python3.6/site-packages/django/core/handlers/base.py", line 179, in _get_response
[Sun Jan 03 10:57:47.365780 2021] [wsgi:error] [pid 968358:tid 140214454810368] [remote 188.147.40.42:30979]     response = wrapped_callback(request, *callback_args, **callback_kwargs)
[Sun Jan 03 10:57:47.365783 2021] [wsgi:error] [pid 968358:tid 140214454810368] [remote 188.147.40.42:30979]   File "/usr/local/lib/python3.6/site-packages/django/views/decorators/cache.py", line 44, in _wrapped_view_func
[Sun Jan 03 10:57:47.365787 2021] [wsgi:error] [pid 968358:tid 140214454810368] [remote 188.147.40.42:30979]     response = view_func(request, *args, **kwargs)
[Sun Jan 03 10:57:47.365790 2021] [wsgi:error] [pid 968358:tid 140214454810368] [remote 188.147.40.42:30979]   File "/usr/local/lib/python3.6/site-packages/django/contrib/admin/sites.py", line 410, in login
[Sun Jan 03 10:57:47.365793 2021] [wsgi:error] [pid 968358:tid 140214454810368] [remote 188.147.40.42:30979]     return LoginView.as_view(**defaults)(request)
[Sun Jan 03 10:57:47.365797 2021] [wsgi:error] [pid 968358:tid 140214454810368] [remote 188.147.40.42:30979]   File "/usr/local/lib/python3.6/site-packages/django/views/generic/base.py", line 70, in view
[Sun Jan 03 10:57:47.365800 2021] [wsgi:error] [pid 968358:tid 140214454810368] [remote 188.147.40.42:30979]     return self.dispatch(request, *args, **kwargs)
[Sun Jan 03 10:57:47.365804 2021] [wsgi:error] [pid 968358:tid 140214454810368] [remote 188.147.40.42:30979]   File "/usr/local/lib/python3.6/site-packages/django/utils/decorators.py", line 43, in _wrapper
[Sun Jan 03 10:57:47.365807 2021] [wsgi:error] [pid 968358:tid 140214454810368] [remote 188.147.40.42:30979]     return bound_method(*args, **kwargs)
[Sun Jan 03 10:57:47.365810 2021] [wsgi:error] [pid 968358:tid 140214454810368] [remote 188.147.40.42:30979]   File "/usr/local/lib/python3.6/site-packages/django/views/decorators/debug.py", line 89, in sensitive_post_parameters_wrapper
[Sun Jan 03 10:57:47.365814 2021] [wsgi:error] [pid 968358:tid 140214454810368] [remote 188.147.40.42:30979]     return view(request, *args, **kwargs)
[Sun Jan 03 10:57:47.365817 2021] [wsgi:error] [pid 968358:tid 140214454810368] [remote 188.147.40.42:30979]   File "/usr/local/lib/python3.6/site-packages/django/utils/decorators.py", line 43, in _wrapper
[Sun Jan 03 10:57:47.365821 2021] [wsgi:error] [pid 968358:tid 140214454810368] [remote 188.147.40.42:30979]     return bound_method(*args, **kwargs)
[Sun Jan 03 10:57:47.365824 2021] [wsgi:error] [pid 968358:tid 140214454810368] [remote 188.147.40.42:30979]   File "/usr/local/lib/python3.6/site-packages/django/utils/decorators.py", line 130, in _wrapped_view
[Sun Jan 03 10:57:47.365828 2021] [wsgi:error] [pid 968358:tid 140214454810368] [remote 188.147.40.42:30979]     response = view_func(request, *args, **kwargs)
[Sun Jan 03 10:57:47.365835 2021] [wsgi:error] [pid 968358:tid 140214454810368] [remote 188.147.40.42:30979]   File "/usr/local/lib/python3.6/site-packages/django/utils/decorators.py", line 43, in _wrapper
[Sun Jan 03 10:57:47.365838 2021] [wsgi:error] [pid 968358:tid 140214454810368] [remote 188.147.40.42:30979]     return bound_method(*args, **kwargs)
[Sun Jan 03 10:57:47.365842 2021] [wsgi:error] [pid 968358:tid 140214454810368] [remote 188.147.40.42:30979]   File "/usr/local/lib/python3.6/site-packages/django/views/decorators/cache.py", line 44, in _wrapped_view_func
[Sun Jan 03 10:57:47.365845 2021] [wsgi:error] [pid 968358:tid 140214454810368] [remote 188.147.40.42:30979]     response = view_func(request, *args, **kwargs)
[Sun Jan 03 10:57:47.365848 2021] [wsgi:error] [pid 968358:tid 140214454810368] [remote 188.147.40.42:30979]   File "/usr/local/lib/python3.6/site-packages/django/contrib/auth/views.py", line 63, in dispatch
[Sun Jan 03 10:57:47.365852 2021] [wsgi:error] [pid 968358:tid 140214454810368] [remote 188.147.40.42:30979]     return super().dispatch(request, *args, **kwargs)
[Sun Jan 03 10:57:47.365855 2021] [wsgi:error] [pid 968358:tid 140214454810368] [remote 188.147.40.42:30979]   File "/usr/local/lib/python3.6/site-packages/django/views/generic/base.py", line 98, in dispatch
[Sun Jan 03 10:57:47.365859 2021] [wsgi:error] [pid 968358:tid 140214454810368] [remote 188.147.40.42:30979]     return handler(request, *args, **kwargs)
[Sun Jan 03 10:57:47.365862 2021] [wsgi:error] [pid 968358:tid 140214454810368] [remote 188.147.40.42:30979]   File "/usr/local/lib/python3.6/site-packages/django/views/generic/edit.py", line 141, in post
[Sun Jan 03 10:57:47.365865 2021] [wsgi:error] [pid 968358:tid 140214454810368] [remote 188.147.40.42:30979]     if form.is_valid():
[Sun Jan 03 10:57:47.365869 2021] [wsgi:error] [pid 968358:tid 140214454810368] [remote 188.147.40.42:30979]   File "/usr/local/lib/python3.6/site-packages/django/forms/forms.py", line 177, in is_valid
[Sun Jan 03 10:57:47.365872 2021] [wsgi:error] [pid 968358:tid 140214454810368] [remote 188.147.40.42:30979]     return self.is_bound and not self.errors
[Sun Jan 03 10:57:47.365875 2021] [wsgi:error] [pid 968358:tid 140214454810368] [remote 188.147.40.42:30979]   File "/usr/local/lib/python3.6/site-packages/django/forms/forms.py", line 172, in errors
[Sun Jan 03 10:57:47.365879 2021] [wsgi:error] [pid 968358:tid 140214454810368] [remote 188.147.40.42:30979]     self.full_clean()
[Sun Jan 03 10:57:47.365882 2021] [wsgi:error] [pid 968358:tid 140214454810368] [remote 188.147.40.42:30979]   File "/usr/local/lib/python3.6/site-packages/django/forms/forms.py", line 375, in full_clean
[Sun Jan 03 10:57:47.365886 2021] [wsgi:error] [pid 968358:tid 140214454810368] [remote 188.147.40.42:30979]     self._clean_form()
[Sun Jan 03 10:57:47.365889 2021] [wsgi:error] [pid 968358:tid 140214454810368] [remote 188.147.40.42:30979]   File "/usr/local/lib/python3.6/site-packages/django/forms/forms.py", line 402, in _clean_form
[Sun Jan 03 10:57:47.365892 2021] [wsgi:error] [pid 968358:tid 140214454810368] [remote 188.147.40.42:30979]     cleaned_data = self.clean()
[Sun Jan 03 10:57:47.365895 2021] [wsgi:error] [pid 968358:tid 140214454810368] [remote 188.147.40.42:30979]   File "/usr/local/lib/python3.6/site-packages/django/contrib/auth/forms.py", line 215, in clean
[Sun Jan 03 10:57:47.365899 2021] [wsgi:error] [pid 968358:tid 140214454810368] [remote 188.147.40.42:30979]     self.user_cache = authenticate(self.request, username=username, password=password)
[Sun Jan 03 10:57:47.365902 2021] [wsgi:error] [pid 968358:tid 140214454810368] [remote 188.147.40.42:30979]   File "/usr/local/lib/python3.6/site-packages/django/contrib/auth/__init__.py", line 73, in authenticate
[Sun Jan 03 10:57:47.365906 2021] [wsgi:error] [pid 968358:tid 140214454810368] [remote 188.147.40.42:30979]     user = backend.authenticate(request, **credentials)
[Sun Jan 03 10:57:47.365912 2021] [wsgi:error] [pid 968358:tid 140214454810368] [remote 188.147.40.42:30979]   File "/usr/local/lib/python3.6/site-packages/django/contrib/auth/backends.py", line 42, in authenticate
[Sun Jan 03 10:57:47.365916 2021] [wsgi:error] [pid 968358:tid 140214454810368] [remote 188.147.40.42:30979]     user = UserModel._default_manager.get_by_natural_key(username)
[Sun Jan 03 10:57:47.365920 2021] [wsgi:error] [pid 968358:tid 140214454810368] [remote 188.147.40.42:30979]   File "/usr/local/lib/python3.6/site-packages/django/contrib/auth/base_user.py", line 45, in get_by_natural_key
[Sun Jan 03 10:57:47.365923 2021] [wsgi:error] [pid 968358:tid 140214454810368] [remote 188.147.40.42:30979]     return self.get(**{self.model.USERNAME_FIELD: username})
[Sun Jan 03 10:57:47.365927 2021] [wsgi:error] [pid 968358:tid 140214454810368] [remote 188.147.40.42:30979]   File "/usr/local/lib/python3.6/site-packages/django/db/models/manager.py", line 85, in manager_method
[Sun Jan 03 10:57:47.365930 2021] [wsgi:error] [pid 968358:tid 140214454810368] [remote 188.147.40.42:30979]     return getattr(self.get_queryset(), name)(*args, **kwargs)
[Sun Jan 03 10:57:47.365934 2021] [wsgi:error] [pid 968358:tid 140214454810368] [remote 188.147.40.42:30979]   File "/usr/local/lib/python3.6/site-packages/django/db/models/query.py", line 425, in get
[Sun Jan 03 10:57:47.365937 2021] [wsgi:error] [pid 968358:tid 140214454810368] [remote 188.147.40.42:30979]     num = len(clone)
[Sun Jan 03 10:57:47.365940 2021] [wsgi:error] [pid 968358:tid 140214454810368] [remote 188.147.40.42:30979]   File "/usr/local/lib/python3.6/site-packages/django/db/models/query.py", line 269, in __len__
[Sun Jan 03 10:57:47.365944 2021] [wsgi:error] [pid 968358:tid 140214454810368] [remote 188.147.40.42:30979]     self._fetch_all()
[Sun Jan 03 10:57:47.365947 2021] [wsgi:error] [pid 968358:tid 140214454810368] [remote 188.147.40.42:30979]   File "/usr/local/lib/python3.6/site-packages/django/db/models/query.py", line 1308, in _fetch_all
[Sun Jan 03 10:57:47.365951 2021] [wsgi:error] [pid 968358:tid 140214454810368] [remote 188.147.40.42:30979]     self._result_cache = list(self._iterable_class(self))
[Sun Jan 03 10:57:47.365954 2021] [wsgi:error] [pid 968358:tid 140214454810368] [remote 188.147.40.42:30979]   File "/usr/local/lib/python3.6/site-packages/django/db/models/query.py", line 53, in __iter__
[Sun Jan 03 10:57:47.365958 2021] [wsgi:error] [pid 968358:tid 140214454810368] [remote 188.147.40.42:30979]     results = compiler.execute_sql(chunked_fetch=self.chunked_fetch, chunk_size=self.chunk_size)
[Sun Jan 03 10:57:47.365961 2021] [wsgi:error] [pid 968358:tid 140214454810368] [remote 188.147.40.42:30979]   File "/usr/local/lib/python3.6/site-packages/django/db/models/sql/compiler.py", line 1156, in execute_sql
[Sun Jan 03 10:57:47.365965 2021] [wsgi:error] [pid 968358:tid 140214454810368] [remote 188.147.40.42:30979]     cursor.execute(sql, params)
[Sun Jan 03 10:57:47.365968 2021] [wsgi:error] [pid 968358:tid 140214454810368] [remote 188.147.40.42:30979]   File "/usr/local/lib/python3.6/site-packages/django/db/backends/utils.py", line 98, in execute
[Sun Jan 03 10:57:47.365989 2021] [wsgi:error] [pid 968358:tid 140214454810368] [remote 188.147.40.42:30979]     return super().execute(sql, params)
[Sun Jan 03 10:57:47.365993 2021] [wsgi:error] [pid 968358:tid 140214454810368] [remote 188.147.40.42:30979]   File "/usr/local/lib/python3.6/site-packages/django/db/backends/utils.py", line 66, in execute
[Sun Jan 03 10:57:47.365996 2021] [wsgi:error] [pid 968358:tid 140214454810368] [remote 188.147.40.42:30979]     return self._execute_with_wrappers(sql, params, many=False, executor=self._execute)
[Sun Jan 03 10:57:47.366000 2021] [wsgi:error] [pid 968358:tid 140214454810368] [remote 188.147.40.42:30979]   File "/usr/local/lib/python3.6/site-packages/django/db/backends/utils.py", line 75, in _execute_with_wrappers
[Sun Jan 03 10:57:47.366003 2021] [wsgi:error] [pid 968358:tid 140214454810368] [remote 188.147.40.42:30979]     return executor(sql, params, many, context)
[Sun Jan 03 10:57:47.366010 2021] [wsgi:error] [pid 968358:tid 140214454810368] [remote 188.147.40.42:30979]   File "/usr/local/lib/python3.6/site-packages/django/db/backends/utils.py", line 84, in _execute
[Sun Jan 03 10:57:47.366013 2021] [wsgi:error] [pid 968358:tid 140214454810368] [remote 188.147.40.42:30979]     return self.cursor.execute(sql, params)
[Sun Jan 03 10:57:47.366017 2021] [wsgi:error] [pid 968358:tid 140214454810368] [remote 188.147.40.42:30979]   File "/usr/local/lib/python3.6/site-packages/django/db/utils.py", line 90, in __exit__
[Sun Jan 03 10:57:47.366020 2021] [wsgi:error] [pid 968358:tid 140214454810368] [remote 188.147.40.42:30979]     raise dj_exc_value.with_traceback(traceback) from exc_value
[Sun Jan 03 10:57:47.366024 2021] [wsgi:error] [pid 968358:tid 140214454810368] [remote 188.147.40.42:30979]   File "/usr/local/lib/python3.6/site-packages/django/db/backends/utils.py", line 84, in _execute
[Sun Jan 03 10:57:47.366027 2021] [wsgi:error] [pid 968358:tid 140214454810368] [remote 188.147.40.42:30979]     return self.cursor.execute(sql, params)
[Sun Jan 03 10:57:47.366030 2021] [wsgi:error] [pid 968358:tid 140214454810368] [remote 188.147.40.42:30979]   File "/usr/local/lib/python3.6/site-packages/django/db/backends/sqlite3/base.py", line 413, in execute
[Sun Jan 03 10:57:47.366034 2021] [wsgi:error] [pid 968358:tid 140214454810368] [remote 188.147.40.42:30979]     return Database.Cursor.execute(self, query, params)
[Sun Jan 03 10:57:47.366039 2021] [wsgi:error] [pid 968358:tid 140214454810368] [remote 188.147.40.42:30979] django.db.utils.OperationalError: no such table: auth_user
[Sun Jan 03 10:57:47.366048 2021] [wsgi:error] [pid 968358:tid 140214454810368] [remote 188.147.40.42:30979] 
Exception ignored in: <bound method BaseEventLoop.__del__ of <_UnixSelectorEventLoop running=False closed=False debug=False>>
Traceback (most recent call last):
  File "/usr/lib64/python3.6/asyncio/base_events.py", line 526, in __del__
NameError: name 'ResourceWarning' is not defined
[Sun Jan 03 13:33:10.752256 2021] [wsgi:error] [pid 1108081:tid 140214566893312] [remote 185.48.128.211:12331] Not Found: /
[Sun Jan 03 13:33:11.018038 2021] [wsgi:error] [pid 1108081:tid 140214558500608] [remote 185.48.128.211:12331] Not Found: /favicon.ico
[Sun Jan 03 13:35:40.652823 2021] [wsgi:error] [pid 1108081:tid 140214566893312] [remote 89.64.42.253:30217] Not Found: /
[Sun Jan 03 13:35:40.953938 2021] [wsgi:error] [pid 1108081:tid 140214558500608] [remote 89.64.42.253:30217] Not Found: /favicon.ico
[Sun Jan 03 13:35:51.789052 2021] [wsgi:error] [pid 1108081:tid 140214558500608] [remote 89.64.42.253:30320] Not Found: /
Exception ignored in: <bound method BaseEventLoop.__del__ of <_UnixSelectorEventLoop running=False closed=False debug=False>>
Traceback (most recent call last):
  File "/usr/lib64/python3.6/asyncio/base_events.py", line 526, in __del__
NameError: name 'ResourceWarning' is not defined
[Sun Jan 03 21:47:54.576523 2021] [wsgi:error] [pid 1109249:tid 140627961001728] [remote 193.19.165.212:52203] Not Found: /
[Sun Jan 03 21:47:54.780691 2021] [wsgi:error] [pid 1109249:tid 140627969394432] [remote 193.19.165.212:52203] Not Found: /favicon.ico
Exception ignored in: <bound method BaseEventLoop.__del__ of <_UnixSelectorEventLoop running=False closed=False debug=False>>
Traceback (most recent call last):
  File "/usr/lib64/python3.6/asyncio/base_events.py", line 526, in __del__
NameError: name 'ResourceWarning' is not defined
[Mon Jan 04 11:48:50.676577 2021] [wsgi:error] [pid 1155187:tid 139964666951424] [remote 91.123.181.237:28927] Not Found: /favicon.ico
[Mon Jan 04 15:48:27.783479 2021] [wsgi:error] [pid 1155187:tid 139964683736832] [remote 188.147.38.41:62389] Not Found: /
[Mon Jan 04 15:48:56.175377 2021] [wsgi:error] [pid 1155187:tid 139964683736832] [remote 188.147.38.41:62237] Not Found: /public_html/index1.html
[Mon Jan 04 15:49:04.019755 2021] [wsgi:error] [pid 1155187:tid 139964666951424] [remote 188.147.38.41:62309] Not Found: /
[Mon Jan 04 15:49:50.684210 2021] [wsgi:error] [pid 1155187:tid 139964683736832] [remote 188.147.38.41:62442] Not Found: /
Exception ignored in: <bound method BaseEventLoop.__del__ of <_UnixSelectorEventLoop running=False closed=False debug=False>>
Traceback (most recent call last):
  File "/usr/lib64/python3.6/asyncio/base_events.py", line 526, in __del__
NameError: name 'ResourceWarning' is not defined
[Mon Jan 04 16:08:45.631064 2021] [wsgi:error] [pid 1170280:tid 140347142944512] [remote 80.54.50.205:53766] Not Found: /favicon.ico
Exception ignored in: <bound method BaseEventLoop.__del__ of <_UnixSelectorEventLoop running=False closed=False debug=False>>
Traceback (most recent call last):
  File "/usr/lib64/python3.6/asyncio/base_events.py", line 526, in __del__
NameError: name 'ResourceWarning' is not defined
[Mon Jan 04 19:30:24.016666 2021] [wsgi:error] [pid 1064:tid 140494603917056] [remote 91.123.176.25:28886] Not Found: /
[Mon Jan 04 19:30:24.355189 2021] [wsgi:error] [pid 1064:tid 140494545168128] [remote 91.123.176.25:28886] Not Found: /favicon.ico
Exception ignored in: <bound method BaseEventLoop.__del__ of <_UnixSelectorEventLoop running=False closed=False debug=False>>
Traceback (most recent call last):
  File "/usr/lib64/python3.6/asyncio/base_events.py", line 526, in __del__
NameError: name 'ResourceWarning' is not defined
[Tue Jan 05 14:13:50.955033 2021] [wsgi:error] [pid 35531:tid 139838887065344] [remote 188.147.38.41:61480] Not Found: /
[Tue Jan 05 14:13:57.284499 2021] [wsgi:error] [pid 35531:tid 139838870279936] [remote 188.147.38.41:61499] Not Found: /
[Tue Jan 05 14:13:58.360250 2021] [wsgi:error] [pid 35531:tid 139838887065344] [remote 188.147.38.41:61499] Not Found: /
Exception ignored in: <bound method BaseEventLoop.__del__ of <_UnixSelectorEventLoop running=False closed=False debug=False>>
Traceback (most recent call last):
  File "/usr/lib64/python3.6/asyncio/base_events.py", line 526, in __del__
NameError: name 'ResourceWarning' is not defined
Exception ignored in: <bound method BaseEventLoop.__del__ of <_UnixSelectorEventLoop running=False closed=False debug=False>>
Traceback (most recent call last):
  File "/usr/lib64/python3.6/asyncio/base_events.py", line 526, in __del__
NameError: name 'ResourceWarning' is not defined
[Tue Jan 05 14:24:19.678536 2021] [wsgi:error] [pid 40996:tid 139838962599680] [remote 188.147.38.41:61599] mod_wsgi (pid=40996): Failed to exec Python script file '/home/g11.labagh.pl/project/wsgi.py'.
[Tue Jan 05 14:24:19.678609 2021] [wsgi:error] [pid 40996:tid 139838962599680] [remote 188.147.38.41:61599] mod_wsgi (pid=40996): Exception occurred processing WSGI script '/home/g11.labagh.pl/project/wsgi.py'.
[Tue Jan 05 14:24:19.680599 2021] [wsgi:error] [pid 40996:tid 139838962599680] [remote 188.147.38.41:61599] Traceback (most recent call last):
[Tue Jan 05 14:24:19.680650 2021] [wsgi:error] [pid 40996:tid 139838962599680] [remote 188.147.38.41:61599]   File "/home/g11.labagh.pl/project/wsgi.py", line 16, in <module>
[Tue Jan 05 14:24:19.680655 2021] [wsgi:error] [pid 40996:tid 139838962599680] [remote 188.147.38.41:61599]     application = get_wsgi_application()
[Tue Jan 05 14:24:19.680661 2021] [wsgi:error] [pid 40996:tid 139838962599680] [remote 188.147.38.41:61599]   File "/usr/local/lib/python3.6/site-packages/django/core/wsgi.py", line 12, in get_wsgi_application
[Tue Jan 05 14:24:19.680666 2021] [wsgi:error] [pid 40996:tid 139838962599680] [remote 188.147.38.41:61599]     django.setup(set_prefix=False)
[Tue Jan 05 14:24:19.680671 2021] [wsgi:error] [pid 40996:tid 139838962599680] [remote 188.147.38.41:61599]   File "/usr/local/lib/python3.6/site-packages/django/__init__.py", line 19, in setup
[Tue Jan 05 14:24:19.680676 2021] [wsgi:error] [pid 40996:tid 139838962599680] [remote 188.147.38.41:61599]     configure_logging(settings.LOGGING_CONFIG, settings.LOGGING)
[Tue Jan 05 14:24:19.680681 2021] [wsgi:error] [pid 40996:tid 139838962599680] [remote 188.147.38.41:61599]   File "/usr/local/lib/python3.6/site-packages/django/conf/__init__.py", line 83, in __getattr__
[Tue Jan 05 14:24:19.680685 2021] [wsgi:error] [pid 40996:tid 139838962599680] [remote 188.147.38.41:61599]     self._setup(name)
[Tue Jan 05 14:24:19.680698 2021] [wsgi:error] [pid 40996:tid 139838962599680] [remote 188.147.38.41:61599]   File "/usr/local/lib/python3.6/site-packages/django/conf/__init__.py", line 70, in _setup
[Tue Jan 05 14:24:19.680702 2021] [wsgi:error] [pid 40996:tid 139838962599680] [remote 188.147.38.41:61599]     self._wrapped = Settings(settings_module)
[Tue Jan 05 14:24:19.680707 2021] [wsgi:error] [pid 40996:tid 139838962599680] [remote 188.147.38.41:61599]   File "/usr/local/lib/python3.6/site-packages/django/conf/__init__.py", line 177, in __init__
[Tue Jan 05 14:24:19.680711 2021] [wsgi:error] [pid 40996:tid 139838962599680] [remote 188.147.38.41:61599]     mod = importlib.import_module(self.SETTINGS_MODULE)
[Tue Jan 05 14:24:19.680716 2021] [wsgi:error] [pid 40996:tid 139838962599680] [remote 188.147.38.41:61599]   File "/usr/lib64/python3.6/importlib/__init__.py", line 126, in import_module
[Tue Jan 05 14:24:19.680719 2021] [wsgi:error] [pid 40996:tid 139838962599680] [remote 188.147.38.41:61599]     return _bootstrap._gcd_import(name[level:], package, level)
[Tue Jan 05 14:24:19.680724 2021] [wsgi:error] [pid 40996:tid 139838962599680] [remote 188.147.38.41:61599]   File "<frozen importlib._bootstrap>", line 994, in _gcd_import
[Tue Jan 05 14:24:19.680729 2021] [wsgi:error] [pid 40996:tid 139838962599680] [remote 188.147.38.41:61599]   File "<frozen importlib._bootstrap>", line 971, in _find_and_load
[Tue Jan 05 14:24:19.680734 2021] [wsgi:error] [pid 40996:tid 139838962599680] [remote 188.147.38.41:61599]   File "<frozen importlib._bootstrap>", line 955, in _find_and_load_unlocked
[Tue Jan 05 14:24:19.680739 2021] [wsgi:error] [pid 40996:tid 139838962599680] [remote 188.147.38.41:61599]   File "<frozen importlib._bootstrap>", line 665, in _load_unlocked
[Tue Jan 05 14:24:19.680744 2021] [wsgi:error] [pid 40996:tid 139838962599680] [remote 188.147.38.41:61599]   File "<frozen importlib._bootstrap_external>", line 678, in exec_module
[Tue Jan 05 14:24:19.680749 2021] [wsgi:error] [pid 40996:tid 139838962599680] [remote 188.147.38.41:61599]   File "<frozen importlib._bootstrap>", line 219, in _call_with_frames_removed
[Tue Jan 05 14:24:19.680754 2021] [wsgi:error] [pid 40996:tid 139838962599680] [remote 188.147.38.41:61599]   File "/home/g11.labagh.pl/project/settings.py", line 128, in <module>
[Tue Jan 05 14:24:19.680770 2021] [wsgi:error] [pid 40996:tid 139838962599680] [remote 188.147.38.41:61599]     os.path.join(BASE_DIR, 'static'),
[Tue Jan 05 14:24:19.680785 2021] [wsgi:error] [pid 40996:tid 139838962599680] [remote 188.147.38.41:61599] NameError: name 'os' is not defined
Exception ignored in: <bound method BaseEventLoop.__del__ of <_UnixSelectorEventLoop running=False closed=False debug=False>>
Traceback (most recent call last):
  File "/usr/lib64/python3.6/asyncio/base_events.py", line 526, in __del__
NameError: name 'ResourceWarning' is not defined
Exception ignored in: <bound method BaseEventLoop.__del__ of <_UnixSelectorEventLoop running=False closed=False debug=False>>
Traceback (most recent call last):
  File "/usr/lib64/python3.6/asyncio/base_events.py", line 526, in __del__
NameError: name 'ResourceWarning' is not defined
Exception ignored in: <bound method BaseEventLoop.__del__ of <_UnixSelectorEventLoop running=False closed=False debug=False>>
Traceback (most recent call last):
  File "/usr/lib64/python3.6/asyncio/base_events.py", line 526, in __del__
NameError: name 'ResourceWarning' is not defined
Exception ignored in: <bound method BaseEventLoop.__del__ of <_UnixSelectorEventLoop running=False closed=False debug=False>>
Traceback (most recent call last):
  File "/usr/lib64/python3.6/asyncio/base_events.py", line 526, in __del__
NameError: name 'ResourceWarning' is not defined
Exception ignored in: <bound method BaseEventLoop.__del__ of <_UnixSelectorEventLoop running=False closed=False debug=False>>
Traceback (most recent call last):
  File "/usr/lib64/python3.6/asyncio/base_events.py", line 526, in __del__
NameError: name 'ResourceWarning' is not defined
Exception ignored in: <bound method BaseEventLoop.__del__ of <_UnixSelectorEventLoop running=False closed=False debug=False>>
Traceback (most recent call last):
  File "/usr/lib64/python3.6/asyncio/base_events.py", line 526, in __del__
NameError: name 'ResourceWarning' is not defined
Exception ignored in: <bound method BaseEventLoop.__del__ of <_UnixSelectorEventLoop running=False closed=False debug=False>>
Traceback (most recent call last):
  File "/usr/lib64/python3.6/asyncio/base_events.py", line 526, in __del__
NameError: name 'ResourceWarning' is not defined
Exception ignored in: <bound method BaseEventLoop.__del__ of <_UnixSelectorEventLoop running=False closed=False debug=False>>
Traceback (most recent call last):
  File "/usr/lib64/python3.6/asyncio/base_events.py", line 526, in __del__
NameError: name 'ResourceWarning' is not defined
Exception ignored in: <bound method BaseEventLoop.__del__ of <_UnixSelectorEventLoop running=False closed=False debug=False>>
Traceback (most recent call last):
  File "/usr/lib64/python3.6/asyncio/base_events.py", line 526, in __del__
NameError: name 'ResourceWarning' is not defined
[Tue Jan 05 17:26:54.163729 2021] [wsgi:error] [pid 49387:tid 139718667769600] [remote 188.147.38.41:61629] mod_wsgi (pid=49387): Failed to exec Python script file '/home/g11.labagh.pl/project/wsgi.py'.
[Tue Jan 05 17:26:54.163803 2021] [wsgi:error] [pid 49387:tid 139718667769600] [remote 188.147.38.41:61629] mod_wsgi (pid=49387): Exception occurred processing WSGI script '/home/g11.labagh.pl/project/wsgi.py'.
[Tue Jan 05 17:26:54.165908 2021] [wsgi:error] [pid 49387:tid 139718667769600] [remote 188.147.38.41:61629] Traceback (most recent call last):
[Tue Jan 05 17:26:54.166124 2021] [wsgi:error] [pid 49387:tid 139718667769600] [remote 188.147.38.41:61629]   File "/home/g11.labagh.pl/project/wsgi.py", line 16, in <module>
[Tue Jan 05 17:26:54.166144 2021] [wsgi:error] [pid 49387:tid 139718667769600] [remote 188.147.38.41:61629]     application = get_wsgi_application()
[Tue Jan 05 17:26:54.166162 2021] [wsgi:error] [pid 49387:tid 139718667769600] [remote 188.147.38.41:61629]   File "/usr/local/lib/python3.6/site-packages/django/core/wsgi.py", line 12, in get_wsgi_application
[Tue Jan 05 17:26:54.166174 2021] [wsgi:error] [pid 49387:tid 139718667769600] [remote 188.147.38.41:61629]     django.setup(set_prefix=False)
[Tue Jan 05 17:26:54.166189 2021] [wsgi:error] [pid 49387:tid 139718667769600] [remote 188.147.38.41:61629]   File "/usr/local/lib/python3.6/site-packages/django/__init__.py", line 24, in setup
[Tue Jan 05 17:26:54.166200 2021] [wsgi:error] [pid 49387:tid 139718667769600] [remote 188.147.38.41:61629]     apps.populate(settings.INSTALLED_APPS)
[Tue Jan 05 17:26:54.166214 2021] [wsgi:error] [pid 49387:tid 139718667769600] [remote 188.147.38.41:61629]   File "/usr/local/lib/python3.6/site-packages/django/apps/registry.py", line 114, in populate
[Tue Jan 05 17:26:54.166226 2021] [wsgi:error] [pid 49387:tid 139718667769600] [remote 188.147.38.41:61629]     app_config.import_models()
[Tue Jan 05 17:26:54.166241 2021] [wsgi:error] [pid 49387:tid 139718667769600] [remote 188.147.38.41:61629]   File "/usr/local/lib/python3.6/site-packages/django/apps/config.py", line 211, in import_models
[Tue Jan 05 17:26:54.166252 2021] [wsgi:error] [pid 49387:tid 139718667769600] [remote 188.147.38.41:61629]     self.models_module = import_module(models_module_name)
[Tue Jan 05 17:26:54.166266 2021] [wsgi:error] [pid 49387:tid 139718667769600] [remote 188.147.38.41:61629]   File "/usr/lib64/python3.6/importlib/__init__.py", line 126, in import_module
[Tue Jan 05 17:26:54.166277 2021] [wsgi:error] [pid 49387:tid 139718667769600] [remote 188.147.38.41:61629]     return _bootstrap._gcd_import(name[level:], package, level)
[Tue Jan 05 17:26:54.166292 2021] [wsgi:error] [pid 49387:tid 139718667769600] [remote 188.147.38.41:61629]   File "<frozen importlib._bootstrap>", line 994, in _gcd_import
[Tue Jan 05 17:26:54.166307 2021] [wsgi:error] [pid 49387:tid 139718667769600] [remote 188.147.38.41:61629]   File "<frozen importlib._bootstrap>", line 971, in _find_and_load
[Tue Jan 05 17:26:54.166347 2021] [wsgi:error] [pid 49387:tid 139718667769600] [remote 188.147.38.41:61629]   File "<frozen importlib._bootstrap>", line 955, in _find_and_load_unlocked
[Tue Jan 05 17:26:54.166362 2021] [wsgi:error] [pid 49387:tid 139718667769600] [remote 188.147.38.41:61629]   File "<frozen importlib._bootstrap>", line 665, in _load_unlocked
[Tue Jan 05 17:26:54.166376 2021] [wsgi:error] [pid 49387:tid 139718667769600] [remote 188.147.38.41:61629]   File "<frozen importlib._bootstrap_external>", line 674, in exec_module
[Tue Jan 05 17:26:54.166391 2021] [wsgi:error] [pid 49387:tid 139718667769600] [remote 188.147.38.41:61629]   File "<frozen importlib._bootstrap_external>", line 781, in get_code
[Tue Jan 05 17:26:54.166404 2021] [wsgi:error] [pid 49387:tid 139718667769600] [remote 188.147.38.41:61629]   File "<frozen importlib._bootstrap_external>", line 741, in source_to_code
[Tue Jan 05 17:26:54.166418 2021] [wsgi:error] [pid 49387:tid 139718667769600] [remote 188.147.38.41:61629]   File "<frozen importlib._bootstrap>", line 219, in _call_with_frames_removed
[Tue Jan 05 17:26:54.166451 2021] [wsgi:error] [pid 49387:tid 139718667769600] [remote 188.147.38.41:61629]   File "/home/g11.labagh.pl/polls/models.py", line 18
[Tue Jan 05 17:26:54.166470 2021] [wsgi:error] [pid 49387:tid 139718667769600] [remote 188.147.38.41:61629]     return self.id_konkursu
[Tue Jan 05 17:26:54.166513 2021] [wsgi:error] [pid 49387:tid 139718667769600] [remote 188.147.38.41:61629]                           ^
[Tue Jan 05 17:26:54.166531 2021] [wsgi:error] [pid 49387:tid 139718667769600] [remote 188.147.38.41:61629] TabError: inconsistent use of tabs and spaces in indentation
[Tue Jan 05 17:26:56.246966 2021] [wsgi:error] [pid 49387:tid 139718659376896] [remote 188.147.38.41:61637] mod_wsgi (pid=49387): Failed to exec Python script file '/home/g11.labagh.pl/project/wsgi.py'.
[Tue Jan 05 17:26:56.247125 2021] [wsgi:error] [pid 49387:tid 139718659376896] [remote 188.147.38.41:61637] mod_wsgi (pid=49387): Exception occurred processing WSGI script '/home/g11.labagh.pl/project/wsgi.py'.
[Tue Jan 05 17:26:56.247438 2021] [wsgi:error] [pid 49387:tid 139718659376896] [remote 188.147.38.41:61637] Traceback (most recent call last):
[Tue Jan 05 17:26:56.247513 2021] [wsgi:error] [pid 49387:tid 139718659376896] [remote 188.147.38.41:61637]   File "/home/g11.labagh.pl/project/wsgi.py", line 16, in <module>
[Tue Jan 05 17:26:56.247525 2021] [wsgi:error] [pid 49387:tid 139718659376896] [remote 188.147.38.41:61637]     application = get_wsgi_application()
[Tue Jan 05 17:26:56.247541 2021] [wsgi:error] [pid 49387:tid 139718659376896] [remote 188.147.38.41:61637]   File "/usr/local/lib/python3.6/site-packages/django/core/wsgi.py", line 12, in get_wsgi_application
[Tue Jan 05 17:26:56.247552 2021] [wsgi:error] [pid 49387:tid 139718659376896] [remote 188.147.38.41:61637]     django.setup(set_prefix=False)
[Tue Jan 05 17:26:56.247565 2021] [wsgi:error] [pid 49387:tid 139718659376896] [remote 188.147.38.41:61637]   File "/usr/local/lib/python3.6/site-packages/django/__init__.py", line 24, in setup
[Tue Jan 05 17:26:56.247575 2021] [wsgi:error] [pid 49387:tid 139718659376896] [remote 188.147.38.41:61637]     apps.populate(settings.INSTALLED_APPS)
[Tue Jan 05 17:26:56.247589 2021] [wsgi:error] [pid 49387:tid 139718659376896] [remote 188.147.38.41:61637]   File "/usr/local/lib/python3.6/site-packages/django/apps/registry.py", line 83, in populate
[Tue Jan 05 17:26:56.247599 2021] [wsgi:error] [pid 49387:tid 139718659376896] [remote 188.147.38.41:61637]     raise RuntimeError("populate() isn't reentrant")
[Tue Jan 05 17:26:56.247640 2021] [wsgi:error] [pid 49387:tid 139718659376896] [remote 188.147.38.41:61637] RuntimeError: populate() isn't reentrant
[Tue Jan 05 17:29:07.346049 2021] [wsgi:error] [pid 49387:tid 139718667769600] [remote 188.147.38.41:61463] mod_wsgi (pid=49387): Failed to exec Python script file '/home/g11.labagh.pl/project/wsgi.py'.
[Tue Jan 05 17:29:07.346281 2021] [wsgi:error] [pid 49387:tid 139718667769600] [remote 188.147.38.41:61463] mod_wsgi (pid=49387): Exception occurred processing WSGI script '/home/g11.labagh.pl/project/wsgi.py'.
[Tue Jan 05 17:29:07.346801 2021] [wsgi:error] [pid 49387:tid 139718667769600] [remote 188.147.38.41:61463] Traceback (most recent call last):
[Tue Jan 05 17:29:07.346885 2021] [wsgi:error] [pid 49387:tid 139718667769600] [remote 188.147.38.41:61463]   File "/home/g11.labagh.pl/project/wsgi.py", line 16, in <module>
[Tue Jan 05 17:29:07.346895 2021] [wsgi:error] [pid 49387:tid 139718667769600] [remote 188.147.38.41:61463]     application = get_wsgi_application()
[Tue Jan 05 17:29:07.346918 2021] [wsgi:error] [pid 49387:tid 139718667769600] [remote 188.147.38.41:61463]   File "/usr/local/lib/python3.6/site-packages/django/core/wsgi.py", line 12, in get_wsgi_application
[Tue Jan 05 17:29:07.346927 2021] [wsgi:error] [pid 49387:tid 139718667769600] [remote 188.147.38.41:61463]     django.setup(set_prefix=False)
[Tue Jan 05 17:29:07.346938 2021] [wsgi:error] [pid 49387:tid 139718667769600] [remote 188.147.38.41:61463]   File "/usr/local/lib/python3.6/site-packages/django/__init__.py", line 24, in setup
[Tue Jan 05 17:29:07.346946 2021] [wsgi:error] [pid 49387:tid 139718667769600] [remote 188.147.38.41:61463]     apps.populate(settings.INSTALLED_APPS)
[Tue Jan 05 17:29:07.346956 2021] [wsgi:error] [pid 49387:tid 139718667769600] [remote 188.147.38.41:61463]   File "/usr/local/lib/python3.6/site-packages/django/apps/registry.py", line 83, in populate
[Tue Jan 05 17:29:07.346964 2021] [wsgi:error] [pid 49387:tid 139718667769600] [remote 188.147.38.41:61463]     raise RuntimeError("populate() isn't reentrant")
[Tue Jan 05 17:29:07.347008 2021] [wsgi:error] [pid 49387:tid 139718667769600] [remote 188.147.38.41:61463] RuntimeError: populate() isn't reentrant
[Tue Jan 05 17:29:08.557900 2021] [wsgi:error] [pid 49387:tid 139718659376896] [remote 188.147.38.41:61475] mod_wsgi (pid=49387): Failed to exec Python script file '/home/g11.labagh.pl/project/wsgi.py'.
[Tue Jan 05 17:29:08.558023 2021] [wsgi:error] [pid 49387:tid 139718659376896] [remote 188.147.38.41:61475] mod_wsgi (pid=49387): Exception occurred processing WSGI script '/home/g11.labagh.pl/project/wsgi.py'.
[Tue Jan 05 17:29:08.558254 2021] [wsgi:error] [pid 49387:tid 139718659376896] [remote 188.147.38.41:61475] Traceback (most recent call last):
[Tue Jan 05 17:29:08.558332 2021] [wsgi:error] [pid 49387:tid 139718659376896] [remote 188.147.38.41:61475]   File "/home/g11.labagh.pl/project/wsgi.py", line 16, in <module>
[Tue Jan 05 17:29:08.558344 2021] [wsgi:error] [pid 49387:tid 139718659376896] [remote 188.147.38.41:61475]     application = get_wsgi_application()
[Tue Jan 05 17:29:08.558360 2021] [wsgi:error] [pid 49387:tid 139718659376896] [remote 188.147.38.41:61475]   File "/usr/local/lib/python3.6/site-packages/django/core/wsgi.py", line 12, in get_wsgi_application
[Tue Jan 05 17:29:08.558370 2021] [wsgi:error] [pid 49387:tid 139718659376896] [remote 188.147.38.41:61475]     django.setup(set_prefix=False)
[Tue Jan 05 17:29:08.558384 2021] [wsgi:error] [pid 49387:tid 139718659376896] [remote 188.147.38.41:61475]   File "/usr/local/lib/python3.6/site-packages/django/__init__.py", line 24, in setup
[Tue Jan 05 17:29:08.558394 2021] [wsgi:error] [pid 49387:tid 139718659376896] [remote 188.147.38.41:61475]     apps.populate(settings.INSTALLED_APPS)
[Tue Jan 05 17:29:08.558407 2021] [wsgi:error] [pid 49387:tid 139718659376896] [remote 188.147.38.41:61475]   File "/usr/local/lib/python3.6/site-packages/django/apps/registry.py", line 83, in populate
[Tue Jan 05 17:29:08.558417 2021] [wsgi:error] [pid 49387:tid 139718659376896] [remote 188.147.38.41:61475]     raise RuntimeError("populate() isn't reentrant")
[Tue Jan 05 17:29:08.558447 2021] [wsgi:error] [pid 49387:tid 139718659376896] [remote 188.147.38.41:61475] RuntimeError: populate() isn't reentrant
[Tue Jan 05 17:29:09.438821 2021] [wsgi:error] [pid 49387:tid 139718667769600] [remote 188.147.38.41:61585] mod_wsgi (pid=49387): Failed to exec Python script file '/home/g11.labagh.pl/project/wsgi.py'.
[Tue Jan 05 17:29:09.438934 2021] [wsgi:error] [pid 49387:tid 139718667769600] [remote 188.147.38.41:61585] mod_wsgi (pid=49387): Exception occurred processing WSGI script '/home/g11.labagh.pl/project/wsgi.py'.
[Tue Jan 05 17:29:09.439192 2021] [wsgi:error] [pid 49387:tid 139718667769600] [remote 188.147.38.41:61585] Traceback (most recent call last):
[Tue Jan 05 17:29:09.439258 2021] [wsgi:error] [pid 49387:tid 139718667769600] [remote 188.147.38.41:61585]   File "/home/g11.labagh.pl/project/wsgi.py", line 16, in <module>
[Tue Jan 05 17:29:09.439270 2021] [wsgi:error] [pid 49387:tid 139718667769600] [remote 188.147.38.41:61585]     application = get_wsgi_application()
[Tue Jan 05 17:29:09.439286 2021] [wsgi:error] [pid 49387:tid 139718667769600] [remote 188.147.38.41:61585]   File "/usr/local/lib/python3.6/site-packages/django/core/wsgi.py", line 12, in get_wsgi_application
[Tue Jan 05 17:29:09.439296 2021] [wsgi:error] [pid 49387:tid 139718667769600] [remote 188.147.38.41:61585]     django.setup(set_prefix=False)
[Tue Jan 05 17:29:09.439310 2021] [wsgi:error] [pid 49387:tid 139718667769600] [remote 188.147.38.41:61585]   File "/usr/local/lib/python3.6/site-packages/django/__init__.py", line 24, in setup
[Tue Jan 05 17:29:09.439320 2021] [wsgi:error] [pid 49387:tid 139718667769600] [remote 188.147.38.41:61585]     apps.populate(settings.INSTALLED_APPS)
[Tue Jan 05 17:29:09.439333 2021] [wsgi:error] [pid 49387:tid 139718667769600] [remote 188.147.38.41:61585]   File "/usr/local/lib/python3.6/site-packages/django/apps/registry.py", line 83, in populate
[Tue Jan 05 17:29:09.439343 2021] [wsgi:error] [pid 49387:tid 139718667769600] [remote 188.147.38.41:61585]     raise RuntimeError("populate() isn't reentrant")
[Tue Jan 05 17:29:09.439372 2021] [wsgi:error] [pid 49387:tid 139718667769600] [remote 188.147.38.41:61585] RuntimeError: populate() isn't reentrant
[Tue Jan 05 17:29:12.448531 2021] [wsgi:error] [pid 49387:tid 139718659376896] [remote 188.147.38.41:61559] mod_wsgi (pid=49387): Failed to exec Python script file '/home/g11.labagh.pl/project/wsgi.py'.
[Tue Jan 05 17:29:12.448635 2021] [wsgi:error] [pid 49387:tid 139718659376896] [remote 188.147.38.41:61559] mod_wsgi (pid=49387): Exception occurred processing WSGI script '/home/g11.labagh.pl/project/wsgi.py'.
[Tue Jan 05 17:29:12.449067 2021] [wsgi:error] [pid 49387:tid 139718659376896] [remote 188.147.38.41:61559] Traceback (most recent call last):
[Tue Jan 05 17:29:12.449148 2021] [wsgi:error] [pid 49387:tid 139718659376896] [remote 188.147.38.41:61559]   File "/home/g11.labagh.pl/project/wsgi.py", line 16, in <module>
[Tue Jan 05 17:29:12.449160 2021] [wsgi:error] [pid 49387:tid 139718659376896] [remote 188.147.38.41:61559]     application = get_wsgi_application()
[Tue Jan 05 17:29:12.449176 2021] [wsgi:error] [pid 49387:tid 139718659376896] [remote 188.147.38.41:61559]   File "/usr/local/lib/python3.6/site-packages/django/core/wsgi.py", line 12, in get_wsgi_application
[Tue Jan 05 17:29:12.449187 2021] [wsgi:error] [pid 49387:tid 139718659376896] [remote 188.147.38.41:61559]     django.setup(set_prefix=False)
[Tue Jan 05 17:29:12.449201 2021] [wsgi:error] [pid 49387:tid 139718659376896] [remote 188.147.38.41:61559]   File "/usr/local/lib/python3.6/site-packages/django/__init__.py", line 24, in setup
[Tue Jan 05 17:29:12.449211 2021] [wsgi:error] [pid 49387:tid 139718659376896] [remote 188.147.38.41:61559]     apps.populate(settings.INSTALLED_APPS)
[Tue Jan 05 17:29:12.449224 2021] [wsgi:error] [pid 49387:tid 139718659376896] [remote 188.147.38.41:61559]   File "/usr/local/lib/python3.6/site-packages/django/apps/registry.py", line 83, in populate
[Tue Jan 05 17:29:12.449234 2021] [wsgi:error] [pid 49387:tid 139718659376896] [remote 188.147.38.41:61559]     raise RuntimeError("populate() isn't reentrant")
[Tue Jan 05 17:29:12.449265 2021] [wsgi:error] [pid 49387:tid 139718659376896] [remote 188.147.38.41:61559] RuntimeError: populate() isn't reentrant
[Tue Jan 05 17:29:31.943086 2021] [wsgi:error] [pid 49387:tid 139718667769600] [remote 188.147.38.41:61454] mod_wsgi (pid=49387): Failed to exec Python script file '/home/g11.labagh.pl/project/wsgi.py'.
[Tue Jan 05 17:29:31.943243 2021] [wsgi:error] [pid 49387:tid 139718667769600] [remote 188.147.38.41:61454] mod_wsgi (pid=49387): Exception occurred processing WSGI script '/home/g11.labagh.pl/project/wsgi.py'.
[Tue Jan 05 17:29:31.943510 2021] [wsgi:error] [pid 49387:tid 139718667769600] [remote 188.147.38.41:61454] Traceback (most recent call last):
[Tue Jan 05 17:29:31.943586 2021] [wsgi:error] [pid 49387:tid 139718667769600] [remote 188.147.38.41:61454]   File "/home/g11.labagh.pl/project/wsgi.py", line 16, in <module>
[Tue Jan 05 17:29:31.943599 2021] [wsgi:error] [pid 49387:tid 139718667769600] [remote 188.147.38.41:61454]     application = get_wsgi_application()
[Tue Jan 05 17:29:31.943623 2021] [wsgi:error] [pid 49387:tid 139718667769600] [remote 188.147.38.41:61454]   File "/usr/local/lib/python3.6/site-packages/django/core/wsgi.py", line 12, in get_wsgi_application
[Tue Jan 05 17:29:31.943634 2021] [wsgi:error] [pid 49387:tid 139718667769600] [remote 188.147.38.41:61454]     django.setup(set_prefix=False)
[Tue Jan 05 17:29:31.943649 2021] [wsgi:error] [pid 49387:tid 139718667769600] [remote 188.147.38.41:61454]   File "/usr/local/lib/python3.6/site-packages/django/__init__.py", line 24, in setup
[Tue Jan 05 17:29:31.943658 2021] [wsgi:error] [pid 49387:tid 139718667769600] [remote 188.147.38.41:61454]     apps.populate(settings.INSTALLED_APPS)
[Tue Jan 05 17:29:31.943672 2021] [wsgi:error] [pid 49387:tid 139718667769600] [remote 188.147.38.41:61454]   File "/usr/local/lib/python3.6/site-packages/django/apps/registry.py", line 83, in populate
[Tue Jan 05 17:29:31.943682 2021] [wsgi:error] [pid 49387:tid 139718667769600] [remote 188.147.38.41:61454]     raise RuntimeError("populate() isn't reentrant")
[Tue Jan 05 17:29:31.943712 2021] [wsgi:error] [pid 49387:tid 139718667769600] [remote 188.147.38.41:61454] RuntimeError: populate() isn't reentrant
[Tue Jan 05 17:29:34.373595 2021] [wsgi:error] [pid 49387:tid 139718659376896] [remote 188.147.38.41:61589] mod_wsgi (pid=49387): Failed to exec Python script file '/home/g11.labagh.pl/project/wsgi.py'.
[Tue Jan 05 17:29:34.373682 2021] [wsgi:error] [pid 49387:tid 139718659376896] [remote 188.147.38.41:61589] mod_wsgi (pid=49387): Exception occurred processing WSGI script '/home/g11.labagh.pl/project/wsgi.py'.
[Tue Jan 05 17:29:34.373933 2021] [wsgi:error] [pid 49387:tid 139718659376896] [remote 188.147.38.41:61589] Traceback (most recent call last):
[Tue Jan 05 17:29:34.373998 2021] [wsgi:error] [pid 49387:tid 139718659376896] [remote 188.147.38.41:61589]   File "/home/g11.labagh.pl/project/wsgi.py", line 16, in <module>
[Tue Jan 05 17:29:34.374008 2021] [wsgi:error] [pid 49387:tid 139718659376896] [remote 188.147.38.41:61589]     application = get_wsgi_application()
[Tue Jan 05 17:29:34.374024 2021] [wsgi:error] [pid 49387:tid 139718659376896] [remote 188.147.38.41:61589]   File "/usr/local/lib/python3.6/site-packages/django/core/wsgi.py", line 12, in get_wsgi_application
[Tue Jan 05 17:29:34.374034 2021] [wsgi:error] [pid 49387:tid 139718659376896] [remote 188.147.38.41:61589]     django.setup(set_prefix=False)
[Tue Jan 05 17:29:34.374048 2021] [wsgi:error] [pid 49387:tid 139718659376896] [remote 188.147.38.41:61589]   File "/usr/local/lib/python3.6/site-packages/django/__init__.py", line 24, in setup
[Tue Jan 05 17:29:34.374059 2021] [wsgi:error] [pid 49387:tid 139718659376896] [remote 188.147.38.41:61589]     apps.populate(settings.INSTALLED_APPS)
[Tue Jan 05 17:29:34.374076 2021] [wsgi:error] [pid 49387:tid 139718659376896] [remote 188.147.38.41:61589]   File "/usr/local/lib/python3.6/site-packages/django/apps/registry.py", line 83, in populate
[Tue Jan 05 17:29:34.374087 2021] [wsgi:error] [pid 49387:tid 139718659376896] [remote 188.147.38.41:61589]     raise RuntimeError("populate() isn't reentrant")
[Tue Jan 05 17:29:34.374117 2021] [wsgi:error] [pid 49387:tid 139718659376896] [remote 188.147.38.41:61589] RuntimeError: populate() isn't reentrant
[Tue Jan 05 17:30:03.950318 2021] [wsgi:error] [pid 49387:tid 139718667769600] [remote 188.147.38.41:61490] mod_wsgi (pid=49387): Failed to exec Python script file '/home/g11.labagh.pl/project/wsgi.py'.
[Tue Jan 05 17:30:03.950540 2021] [wsgi:error] [pid 49387:tid 139718667769600] [remote 188.147.38.41:61490] mod_wsgi (pid=49387): Exception occurred processing WSGI script '/home/g11.labagh.pl/project/wsgi.py'.
[Tue Jan 05 17:30:03.951685 2021] [wsgi:error] [pid 49387:tid 139718667769600] [remote 188.147.38.41:61490] Traceback (most recent call last):
[Tue Jan 05 17:30:03.951847 2021] [wsgi:error] [pid 49387:tid 139718667769600] [remote 188.147.38.41:61490]   File "/home/g11.labagh.pl/project/wsgi.py", line 16, in <module>
[Tue Jan 05 17:30:03.951866 2021] [wsgi:error] [pid 49387:tid 139718667769600] [remote 188.147.38.41:61490]     application = get_wsgi_application()
[Tue Jan 05 17:30:03.951883 2021] [wsgi:error] [pid 49387:tid 139718667769600] [remote 188.147.38.41:61490]   File "/usr/local/lib/python3.6/site-packages/django/core/wsgi.py", line 12, in get_wsgi_application
[Tue Jan 05 17:30:03.951895 2021] [wsgi:error] [pid 49387:tid 139718667769600] [remote 188.147.38.41:61490]     django.setup(set_prefix=False)
[Tue Jan 05 17:30:03.951910 2021] [wsgi:error] [pid 49387:tid 139718667769600] [remote 188.147.38.41:61490]   File "/usr/local/lib/python3.6/site-packages/django/__init__.py", line 24, in setup
[Tue Jan 05 17:30:03.951921 2021] [wsgi:error] [pid 49387:tid 139718667769600] [remote 188.147.38.41:61490]     apps.populate(settings.INSTALLED_APPS)
[Tue Jan 05 17:30:03.951936 2021] [wsgi:error] [pid 49387:tid 139718667769600] [remote 188.147.38.41:61490]   File "/usr/local/lib/python3.6/site-packages/django/apps/registry.py", line 83, in populate
[Tue Jan 05 17:30:03.951947 2021] [wsgi:error] [pid 49387:tid 139718667769600] [remote 188.147.38.41:61490]     raise RuntimeError("populate() isn't reentrant")
[Tue Jan 05 17:30:03.951987 2021] [wsgi:error] [pid 49387:tid 139718667769600] [remote 188.147.38.41:61490] RuntimeError: populate() isn't reentrant
[Tue Jan 05 17:30:05.297872 2021] [wsgi:error] [pid 49387:tid 139718659376896] [remote 188.147.38.41:61631] mod_wsgi (pid=49387): Failed to exec Python script file '/home/g11.labagh.pl/project/wsgi.py'.
[Tue Jan 05 17:30:05.297977 2021] [wsgi:error] [pid 49387:tid 139718659376896] [remote 188.147.38.41:61631] mod_wsgi (pid=49387): Exception occurred processing WSGI script '/home/g11.labagh.pl/project/wsgi.py'.
[Tue Jan 05 17:30:05.298197 2021] [wsgi:error] [pid 49387:tid 139718659376896] [remote 188.147.38.41:61631] Traceback (most recent call last):
[Tue Jan 05 17:30:05.298254 2021] [wsgi:error] [pid 49387:tid 139718659376896] [remote 188.147.38.41:61631]   File "/home/g11.labagh.pl/project/wsgi.py", line 16, in <module>
[Tue Jan 05 17:30:05.298265 2021] [wsgi:error] [pid 49387:tid 139718659376896] [remote 188.147.38.41:61631]     application = get_wsgi_application()
[Tue Jan 05 17:30:05.298279 2021] [wsgi:error] [pid 49387:tid 139718659376896] [remote 188.147.38.41:61631]   File "/usr/local/lib/python3.6/site-packages/django/core/wsgi.py", line 12, in get_wsgi_application
[Tue Jan 05 17:30:05.298288 2021] [wsgi:error] [pid 49387:tid 139718659376896] [remote 188.147.38.41:61631]     django.setup(set_prefix=False)
[Tue Jan 05 17:30:05.298300 2021] [wsgi:error] [pid 49387:tid 139718659376896] [remote 188.147.38.41:61631]   File "/usr/local/lib/python3.6/site-packages/django/__init__.py", line 24, in setup
[Tue Jan 05 17:30:05.298310 2021] [wsgi:error] [pid 49387:tid 139718659376896] [remote 188.147.38.41:61631]     apps.populate(settings.INSTALLED_APPS)
[Tue Jan 05 17:30:05.298321 2021] [wsgi:error] [pid 49387:tid 139718659376896] [remote 188.147.38.41:61631]   File "/usr/local/lib/python3.6/site-packages/django/apps/registry.py", line 83, in populate
[Tue Jan 05 17:30:05.298331 2021] [wsgi:error] [pid 49387:tid 139718659376896] [remote 188.147.38.41:61631]     raise RuntimeError("populate() isn't reentrant")
[Tue Jan 05 17:30:05.298357 2021] [wsgi:error] [pid 49387:tid 139718659376896] [remote 188.147.38.41:61631] RuntimeError: populate() isn't reentrant
[Tue Jan 05 17:32:07.566123 2021] [wsgi:error] [pid 49387:tid 139718667769600] [remote 188.147.38.41:61624] mod_wsgi (pid=49387): Failed to exec Python script file '/home/g11.labagh.pl/project/wsgi.py'.
[Tue Jan 05 17:32:07.566428 2021] [wsgi:error] [pid 49387:tid 139718667769600] [remote 188.147.38.41:61624] mod_wsgi (pid=49387): Exception occurred processing WSGI script '/home/g11.labagh.pl/project/wsgi.py'.
[Tue Jan 05 17:32:07.567326 2021] [wsgi:error] [pid 49387:tid 139718667769600] [remote 188.147.38.41:61624] Traceback (most recent call last):
[Tue Jan 05 17:32:07.567459 2021] [wsgi:error] [pid 49387:tid 139718667769600] [remote 188.147.38.41:61624]   File "/home/g11.labagh.pl/project/wsgi.py", line 16, in <module>
[Tue Jan 05 17:32:07.567488 2021] [wsgi:error] [pid 49387:tid 139718667769600] [remote 188.147.38.41:61624]     application = get_wsgi_application()
[Tue Jan 05 17:32:07.567552 2021] [wsgi:error] [pid 49387:tid 139718667769600] [remote 188.147.38.41:61624]   File "/usr/local/lib/python3.6/site-packages/django/core/wsgi.py", line 12, in get_wsgi_application
[Tue Jan 05 17:32:07.567572 2021] [wsgi:error] [pid 49387:tid 139718667769600] [remote 188.147.38.41:61624]     django.setup(set_prefix=False)
[Tue Jan 05 17:32:07.567592 2021] [wsgi:error] [pid 49387:tid 139718667769600] [remote 188.147.38.41:61624]   File "/usr/local/lib/python3.6/site-packages/django/__init__.py", line 24, in setup
[Tue Jan 05 17:32:07.567603 2021] [wsgi:error] [pid 49387:tid 139718667769600] [remote 188.147.38.41:61624]     apps.populate(settings.INSTALLED_APPS)
[Tue Jan 05 17:32:07.567618 2021] [wsgi:error] [pid 49387:tid 139718667769600] [remote 188.147.38.41:61624]   File "/usr/local/lib/python3.6/site-packages/django/apps/registry.py", line 83, in populate
[Tue Jan 05 17:32:07.567629 2021] [wsgi:error] [pid 49387:tid 139718667769600] [remote 188.147.38.41:61624]     raise RuntimeError("populate() isn't reentrant")
[Tue Jan 05 17:32:07.567691 2021] [wsgi:error] [pid 49387:tid 139718667769600] [remote 188.147.38.41:61624] RuntimeError: populate() isn't reentrant
[Tue Jan 05 17:32:18.352430 2021] [wsgi:error] [pid 49387:tid 139718659376896] [remote 188.147.38.41:61614] mod_wsgi (pid=49387): Failed to exec Python script file '/home/g11.labagh.pl/project/wsgi.py'.
[Tue Jan 05 17:32:18.352505 2021] [wsgi:error] [pid 49387:tid 139718659376896] [remote 188.147.38.41:61614] mod_wsgi (pid=49387): Exception occurred processing WSGI script '/home/g11.labagh.pl/project/wsgi.py'.
[Tue Jan 05 17:32:18.352702 2021] [wsgi:error] [pid 49387:tid 139718659376896] [remote 188.147.38.41:61614] Traceback (most recent call last):
[Tue Jan 05 17:32:18.352747 2021] [wsgi:error] [pid 49387:tid 139718659376896] [remote 188.147.38.41:61614]   File "/home/g11.labagh.pl/project/wsgi.py", line 16, in <module>
[Tue Jan 05 17:32:18.352755 2021] [wsgi:error] [pid 49387:tid 139718659376896] [remote 188.147.38.41:61614]     application = get_wsgi_application()
[Tue Jan 05 17:32:18.352785 2021] [wsgi:error] [pid 49387:tid 139718659376896] [remote 188.147.38.41:61614]   File "/usr/local/lib/python3.6/site-packages/django/core/wsgi.py", line 12, in get_wsgi_application
[Tue Jan 05 17:32:18.352791 2021] [wsgi:error] [pid 49387:tid 139718659376896] [remote 188.147.38.41:61614]     django.setup(set_prefix=False)
[Tue Jan 05 17:32:18.352799 2021] [wsgi:error] [pid 49387:tid 139718659376896] [remote 188.147.38.41:61614]   File "/usr/local/lib/python3.6/site-packages/django/__init__.py", line 24, in setup
[Tue Jan 05 17:32:18.352805 2021] [wsgi:error] [pid 49387:tid 139718659376896] [remote 188.147.38.41:61614]     apps.populate(settings.INSTALLED_APPS)
[Tue Jan 05 17:32:18.352813 2021] [wsgi:error] [pid 49387:tid 139718659376896] [remote 188.147.38.41:61614]   File "/usr/local/lib/python3.6/site-packages/django/apps/registry.py", line 83, in populate
[Tue Jan 05 17:32:18.352822 2021] [wsgi:error] [pid 49387:tid 139718659376896] [remote 188.147.38.41:61614]     raise RuntimeError("populate() isn't reentrant")
[Tue Jan 05 17:32:18.352886 2021] [wsgi:error] [pid 49387:tid 139718659376896] [remote 188.147.38.41:61614] RuntimeError: populate() isn't reentrant
[Tue Jan 05 17:33:37.536868 2021] [wsgi:error] [pid 49387:tid 139718667769600] [remote 188.147.38.41:61559] mod_wsgi (pid=49387): Failed to exec Python script file '/home/g11.labagh.pl/project/wsgi.py'.
[Tue Jan 05 17:33:37.537033 2021] [wsgi:error] [pid 49387:tid 139718667769600] [remote 188.147.38.41:61559] mod_wsgi (pid=49387): Exception occurred processing WSGI script '/home/g11.labagh.pl/project/wsgi.py'.
[Tue Jan 05 17:33:37.538018 2021] [wsgi:error] [pid 49387:tid 139718667769600] [remote 188.147.38.41:61559] Traceback (most recent call last):
[Tue Jan 05 17:33:37.538130 2021] [wsgi:error] [pid 49387:tid 139718667769600] [remote 188.147.38.41:61559]   File "/home/g11.labagh.pl/project/wsgi.py", line 16, in <module>
[Tue Jan 05 17:33:37.538145 2021] [wsgi:error] [pid 49387:tid 139718667769600] [remote 188.147.38.41:61559]     application = get_wsgi_application()
[Tue Jan 05 17:33:37.538169 2021] [wsgi:error] [pid 49387:tid 139718667769600] [remote 188.147.38.41:61559]   File "/usr/local/lib/python3.6/site-packages/django/core/wsgi.py", line 12, in get_wsgi_application
[Tue Jan 05 17:33:37.538181 2021] [wsgi:error] [pid 49387:tid 139718667769600] [remote 188.147.38.41:61559]     django.setup(set_prefix=False)
[Tue Jan 05 17:33:37.538196 2021] [wsgi:error] [pid 49387:tid 139718667769600] [remote 188.147.38.41:61559]   File "/usr/local/lib/python3.6/site-packages/django/__init__.py", line 24, in setup
[Tue Jan 05 17:33:37.538207 2021] [wsgi:error] [pid 49387:tid 139718667769600] [remote 188.147.38.41:61559]     apps.populate(settings.INSTALLED_APPS)
[Tue Jan 05 17:33:37.538222 2021] [wsgi:error] [pid 49387:tid 139718667769600] [remote 188.147.38.41:61559]   File "/usr/local/lib/python3.6/site-packages/django/apps/registry.py", line 83, in populate
[Tue Jan 05 17:33:37.538233 2021] [wsgi:error] [pid 49387:tid 139718667769600] [remote 188.147.38.41:61559]     raise RuntimeError("populate() isn't reentrant")
[Tue Jan 05 17:33:37.538276 2021] [wsgi:error] [pid 49387:tid 139718667769600] [remote 188.147.38.41:61559] RuntimeError: populate() isn't reentrant
[Tue Jan 05 17:33:38.576695 2021] [wsgi:error] [pid 49387:tid 139718659376896] [remote 188.147.38.41:61440] mod_wsgi (pid=49387): Failed to exec Python script file '/home/g11.labagh.pl/project/wsgi.py'.
[Tue Jan 05 17:33:38.576860 2021] [wsgi:error] [pid 49387:tid 139718659376896] [remote 188.147.38.41:61440] mod_wsgi (pid=49387): Exception occurred processing WSGI script '/home/g11.labagh.pl/project/wsgi.py'.
[Tue Jan 05 17:33:38.577092 2021] [wsgi:error] [pid 49387:tid 139718659376896] [remote 188.147.38.41:61440] Traceback (most recent call last):
[Tue Jan 05 17:33:38.577159 2021] [wsgi:error] [pid 49387:tid 139718659376896] [remote 188.147.38.41:61440]   File "/home/g11.labagh.pl/project/wsgi.py", line 16, in <module>
[Tue Jan 05 17:33:38.577171 2021] [wsgi:error] [pid 49387:tid 139718659376896] [remote 188.147.38.41:61440]     application = get_wsgi_application()
[Tue Jan 05 17:33:38.577188 2021] [wsgi:error] [pid 49387:tid 139718659376896] [remote 188.147.38.41:61440]   File "/usr/local/lib/python3.6/site-packages/django/core/wsgi.py", line 12, in get_wsgi_application
[Tue Jan 05 17:33:38.577199 2021] [wsgi:error] [pid 49387:tid 139718659376896] [remote 188.147.38.41:61440]     django.setup(set_prefix=False)
[Tue Jan 05 17:33:38.577214 2021] [wsgi:error] [pid 49387:tid 139718659376896] [remote 188.147.38.41:61440]   File "/usr/local/lib/python3.6/site-packages/django/__init__.py", line 24, in setup
[Tue Jan 05 17:33:38.577225 2021] [wsgi:error] [pid 49387:tid 139718659376896] [remote 188.147.38.41:61440]     apps.populate(settings.INSTALLED_APPS)
[Tue Jan 05 17:33:38.577239 2021] [wsgi:error] [pid 49387:tid 139718659376896] [remote 188.147.38.41:61440]   File "/usr/local/lib/python3.6/site-packages/django/apps/registry.py", line 83, in populate
[Tue Jan 05 17:33:38.577250 2021] [wsgi:error] [pid 49387:tid 139718659376896] [remote 188.147.38.41:61440]     raise RuntimeError("populate() isn't reentrant")
[Tue Jan 05 17:33:38.577305 2021] [wsgi:error] [pid 49387:tid 139718659376896] [remote 188.147.38.41:61440] RuntimeError: populate() isn't reentrant
[Tue Jan 05 17:33:39.435249 2021] [wsgi:error] [pid 49387:tid 139718667769600] [remote 188.147.38.41:61480] mod_wsgi (pid=49387): Failed to exec Python script file '/home/g11.labagh.pl/project/wsgi.py'.
[Tue Jan 05 17:33:39.435344 2021] [wsgi:error] [pid 49387:tid 139718667769600] [remote 188.147.38.41:61480] mod_wsgi (pid=49387): Exception occurred processing WSGI script '/home/g11.labagh.pl/project/wsgi.py'.
[Tue Jan 05 17:33:39.435580 2021] [wsgi:error] [pid 49387:tid 139718667769600] [remote 188.147.38.41:61480] Traceback (most recent call last):
[Tue Jan 05 17:33:39.435645 2021] [wsgi:error] [pid 49387:tid 139718667769600] [remote 188.147.38.41:61480]   File "/home/g11.labagh.pl/project/wsgi.py", line 16, in <module>
[Tue Jan 05 17:33:39.435657 2021] [wsgi:error] [pid 49387:tid 139718667769600] [remote 188.147.38.41:61480]     application = get_wsgi_application()
[Tue Jan 05 17:33:39.435673 2021] [wsgi:error] [pid 49387:tid 139718667769600] [remote 188.147.38.41:61480]   File "/usr/local/lib/python3.6/site-packages/django/core/wsgi.py", line 12, in get_wsgi_application
[Tue Jan 05 17:33:39.435684 2021] [wsgi:error] [pid 49387:tid 139718667769600] [remote 188.147.38.41:61480]     django.setup(set_prefix=False)
[Tue Jan 05 17:33:39.435697 2021] [wsgi:error] [pid 49387:tid 139718667769600] [remote 188.147.38.41:61480]   File "/usr/local/lib/python3.6/site-packages/django/__init__.py", line 24, in setup
[Tue Jan 05 17:33:39.435707 2021] [wsgi:error] [pid 49387:tid 139718667769600] [remote 188.147.38.41:61480]     apps.populate(settings.INSTALLED_APPS)
[Tue Jan 05 17:33:39.435720 2021] [wsgi:error] [pid 49387:tid 139718667769600] [remote 188.147.38.41:61480]   File "/usr/local/lib/python3.6/site-packages/django/apps/registry.py", line 83, in populate
[Tue Jan 05 17:33:39.435730 2021] [wsgi:error] [pid 49387:tid 139718667769600] [remote 188.147.38.41:61480]     raise RuntimeError("populate() isn't reentrant")
[Tue Jan 05 17:33:39.435790 2021] [wsgi:error] [pid 49387:tid 139718667769600] [remote 188.147.38.41:61480] RuntimeError: populate() isn't reentrant
[Tue Jan 05 17:33:40.317480 2021] [wsgi:error] [pid 49387:tid 139718659376896] [remote 188.147.38.41:61492] mod_wsgi (pid=49387): Failed to exec Python script file '/home/g11.labagh.pl/project/wsgi.py'.
[Tue Jan 05 17:33:40.317623 2021] [wsgi:error] [pid 49387:tid 139718659376896] [remote 188.147.38.41:61492] mod_wsgi (pid=49387): Exception occurred processing WSGI script '/home/g11.labagh.pl/project/wsgi.py'.
[Tue Jan 05 17:33:40.317924 2021] [wsgi:error] [pid 49387:tid 139718659376896] [remote 188.147.38.41:61492] Traceback (most recent call last):
[Tue Jan 05 17:33:40.318034 2021] [wsgi:error] [pid 49387:tid 139718659376896] [remote 188.147.38.41:61492]   File "/home/g11.labagh.pl/project/wsgi.py", line 16, in <module>
[Tue Jan 05 17:33:40.318049 2021] [wsgi:error] [pid 49387:tid 139718659376896] [remote 188.147.38.41:61492]     application = get_wsgi_application()
[Tue Jan 05 17:33:40.318066 2021] [wsgi:error] [pid 49387:tid 139718659376896] [remote 188.147.38.41:61492]   File "/usr/local/lib/python3.6/site-packages/django/core/wsgi.py", line 12, in get_wsgi_application
[Tue Jan 05 17:33:40.318076 2021] [wsgi:error] [pid 49387:tid 139718659376896] [remote 188.147.38.41:61492]     django.setup(set_prefix=False)
[Tue Jan 05 17:33:40.318090 2021] [wsgi:error] [pid 49387:tid 139718659376896] [remote 188.147.38.41:61492]   File "/usr/local/lib/python3.6/site-packages/django/__init__.py", line 24, in setup
[Tue Jan 05 17:33:40.318100 2021] [wsgi:error] [pid 49387:tid 139718659376896] [remote 188.147.38.41:61492]     apps.populate(settings.INSTALLED_APPS)
[Tue Jan 05 17:33:40.318113 2021] [wsgi:error] [pid 49387:tid 139718659376896] [remote 188.147.38.41:61492]   File "/usr/local/lib/python3.6/site-packages/django/apps/registry.py", line 83, in populate
[Tue Jan 05 17:33:40.318168 2021] [wsgi:error] [pid 49387:tid 139718659376896] [remote 188.147.38.41:61492]     raise RuntimeError("populate() isn't reentrant")
[Tue Jan 05 17:33:40.318203 2021] [wsgi:error] [pid 49387:tid 139718659376896] [remote 188.147.38.41:61492] RuntimeError: populate() isn't reentrant
[Tue Jan 05 17:37:01.976352 2021] [wsgi:error] [pid 49387:tid 139718667769600] [remote 188.147.38.41:61528] mod_wsgi (pid=49387): Failed to exec Python script file '/home/g11.labagh.pl/project/wsgi.py'.
[Tue Jan 05 17:37:01.976520 2021] [wsgi:error] [pid 49387:tid 139718667769600] [remote 188.147.38.41:61528] mod_wsgi (pid=49387): Exception occurred processing WSGI script '/home/g11.labagh.pl/project/wsgi.py'.
[Tue Jan 05 17:37:01.976895 2021] [wsgi:error] [pid 49387:tid 139718667769600] [remote 188.147.38.41:61528] Traceback (most recent call last):
[Tue Jan 05 17:37:01.976952 2021] [wsgi:error] [pid 49387:tid 139718667769600] [remote 188.147.38.41:61528]   File "/home/g11.labagh.pl/project/wsgi.py", line 16, in <module>
[Tue Jan 05 17:37:01.976959 2021] [wsgi:error] [pid 49387:tid 139718667769600] [remote 188.147.38.41:61528]     application = get_wsgi_application()
[Tue Jan 05 17:37:01.976976 2021] [wsgi:error] [pid 49387:tid 139718667769600] [remote 188.147.38.41:61528]   File "/usr/local/lib/python3.6/site-packages/django/core/wsgi.py", line 12, in get_wsgi_application
[Tue Jan 05 17:37:01.976982 2021] [wsgi:error] [pid 49387:tid 139718667769600] [remote 188.147.38.41:61528]     django.setup(set_prefix=False)
[Tue Jan 05 17:37:01.976991 2021] [wsgi:error] [pid 49387:tid 139718667769600] [remote 188.147.38.41:61528]   File "/usr/local/lib/python3.6/site-packages/django/__init__.py", line 24, in setup
[Tue Jan 05 17:37:01.976996 2021] [wsgi:error] [pid 49387:tid 139718667769600] [remote 188.147.38.41:61528]     apps.populate(settings.INSTALLED_APPS)
[Tue Jan 05 17:37:01.977004 2021] [wsgi:error] [pid 49387:tid 139718667769600] [remote 188.147.38.41:61528]   File "/usr/local/lib/python3.6/site-packages/django/apps/registry.py", line 83, in populate
[Tue Jan 05 17:37:01.977010 2021] [wsgi:error] [pid 49387:tid 139718667769600] [remote 188.147.38.41:61528]     raise RuntimeError("populate() isn't reentrant")
[Tue Jan 05 17:37:01.977042 2021] [wsgi:error] [pid 49387:tid 139718667769600] [remote 188.147.38.41:61528] RuntimeError: populate() isn't reentrant
[Tue Jan 05 17:43:19.063384 2021] [wsgi:error] [pid 49387:tid 139718659376896] [remote 188.147.38.41:61506] mod_wsgi (pid=49387): Failed to exec Python script file '/home/g11.labagh.pl/project/wsgi.py'.
[Tue Jan 05 17:43:19.063588 2021] [wsgi:error] [pid 49387:tid 139718659376896] [remote 188.147.38.41:61506] mod_wsgi (pid=49387): Exception occurred processing WSGI script '/home/g11.labagh.pl/project/wsgi.py'.
[Tue Jan 05 17:43:19.064145 2021] [wsgi:error] [pid 49387:tid 139718659376896] [remote 188.147.38.41:61506] Traceback (most recent call last):
[Tue Jan 05 17:43:19.064216 2021] [wsgi:error] [pid 49387:tid 139718659376896] [remote 188.147.38.41:61506]   File "/home/g11.labagh.pl/project/wsgi.py", line 16, in <module>
[Tue Jan 05 17:43:19.064224 2021] [wsgi:error] [pid 49387:tid 139718659376896] [remote 188.147.38.41:61506]     application = get_wsgi_application()
[Tue Jan 05 17:43:19.064237 2021] [wsgi:error] [pid 49387:tid 139718659376896] [remote 188.147.38.41:61506]   File "/usr/local/lib/python3.6/site-packages/django/core/wsgi.py", line 12, in get_wsgi_application
[Tue Jan 05 17:43:19.064243 2021] [wsgi:error] [pid 49387:tid 139718659376896] [remote 188.147.38.41:61506]     django.setup(set_prefix=False)
[Tue Jan 05 17:43:19.064254 2021] [wsgi:error] [pid 49387:tid 139718659376896] [remote 188.147.38.41:61506]   File "/usr/local/lib/python3.6/site-packages/django/__init__.py", line 24, in setup
[Tue Jan 05 17:43:19.064260 2021] [wsgi:error] [pid 49387:tid 139718659376896] [remote 188.147.38.41:61506]     apps.populate(settings.INSTALLED_APPS)
[Tue Jan 05 17:43:19.064268 2021] [wsgi:error] [pid 49387:tid 139718659376896] [remote 188.147.38.41:61506]   File "/usr/local/lib/python3.6/site-packages/django/apps/registry.py", line 83, in populate
[Tue Jan 05 17:43:19.064287 2021] [wsgi:error] [pid 49387:tid 139718659376896] [remote 188.147.38.41:61506]     raise RuntimeError("populate() isn't reentrant")
[Tue Jan 05 17:43:19.064324 2021] [wsgi:error] [pid 49387:tid 139718659376896] [remote 188.147.38.41:61506] RuntimeError: populate() isn't reentrant
[Tue Jan 05 17:43:19.989721 2021] [wsgi:error] [pid 49387:tid 139718667769600] [remote 188.147.38.41:61577] mod_wsgi (pid=49387): Failed to exec Python script file '/home/g11.labagh.pl/project/wsgi.py'.
[Tue Jan 05 17:43:19.989893 2021] [wsgi:error] [pid 49387:tid 139718667769600] [remote 188.147.38.41:61577] mod_wsgi (pid=49387): Exception occurred processing WSGI script '/home/g11.labagh.pl/project/wsgi.py'.
[Tue Jan 05 17:43:19.990216 2021] [wsgi:error] [pid 49387:tid 139718667769600] [remote 188.147.38.41:61577] Traceback (most recent call last):
[Tue Jan 05 17:43:19.990315 2021] [wsgi:error] [pid 49387:tid 139718667769600] [remote 188.147.38.41:61577]   File "/home/g11.labagh.pl/project/wsgi.py", line 16, in <module>
[Tue Jan 05 17:43:19.990329 2021] [wsgi:error] [pid 49387:tid 139718667769600] [remote 188.147.38.41:61577]     application = get_wsgi_application()
[Tue Jan 05 17:43:19.990354 2021] [wsgi:error] [pid 49387:tid 139718667769600] [remote 188.147.38.41:61577]   File "/usr/local/lib/python3.6/site-packages/django/core/wsgi.py", line 12, in get_wsgi_application
[Tue Jan 05 17:43:19.990366 2021] [wsgi:error] [pid 49387:tid 139718667769600] [remote 188.147.38.41:61577]     django.setup(set_prefix=False)
[Tue Jan 05 17:43:19.990381 2021] [wsgi:error] [pid 49387:tid 139718667769600] [remote 188.147.38.41:61577]   File "/usr/local/lib/python3.6/site-packages/django/__init__.py", line 24, in setup
[Tue Jan 05 17:43:19.990391 2021] [wsgi:error] [pid 49387:tid 139718667769600] [remote 188.147.38.41:61577]     apps.populate(settings.INSTALLED_APPS)
[Tue Jan 05 17:43:19.990405 2021] [wsgi:error] [pid 49387:tid 139718667769600] [remote 188.147.38.41:61577]   File "/usr/local/lib/python3.6/site-packages/django/apps/registry.py", line 83, in populate
[Tue Jan 05 17:43:19.990415 2021] [wsgi:error] [pid 49387:tid 139718667769600] [remote 188.147.38.41:61577]     raise RuntimeError("populate() isn't reentrant")
[Tue Jan 05 17:43:19.990447 2021] [wsgi:error] [pid 49387:tid 139718667769600] [remote 188.147.38.41:61577] RuntimeError: populate() isn't reentrant
[Tue Jan 05 17:43:20.776156 2021] [wsgi:error] [pid 49387:tid 139718659376896] [remote 188.147.38.41:61509] mod_wsgi (pid=49387): Failed to exec Python script file '/home/g11.labagh.pl/project/wsgi.py'.
[Tue Jan 05 17:43:20.776254 2021] [wsgi:error] [pid 49387:tid 139718659376896] [remote 188.147.38.41:61509] mod_wsgi (pid=49387): Exception occurred processing WSGI script '/home/g11.labagh.pl/project/wsgi.py'.
[Tue Jan 05 17:43:20.776505 2021] [wsgi:error] [pid 49387:tid 139718659376896] [remote 188.147.38.41:61509] Traceback (most recent call last):
[Tue Jan 05 17:43:20.776557 2021] [wsgi:error] [pid 49387:tid 139718659376896] [remote 188.147.38.41:61509]   File "/home/g11.labagh.pl/project/wsgi.py", line 16, in <module>
[Tue Jan 05 17:43:20.776566 2021] [wsgi:error] [pid 49387:tid 139718659376896] [remote 188.147.38.41:61509]     application = get_wsgi_application()
[Tue Jan 05 17:43:20.776577 2021] [wsgi:error] [pid 49387:tid 139718659376896] [remote 188.147.38.41:61509]   File "/usr/local/lib/python3.6/site-packages/django/core/wsgi.py", line 12, in get_wsgi_application
[Tue Jan 05 17:43:20.776583 2021] [wsgi:error] [pid 49387:tid 139718659376896] [remote 188.147.38.41:61509]     django.setup(set_prefix=False)
[Tue Jan 05 17:43:20.776591 2021] [wsgi:error] [pid 49387:tid 139718659376896] [remote 188.147.38.41:61509]   File "/usr/local/lib/python3.6/site-packages/django/__init__.py", line 24, in setup
[Tue Jan 05 17:43:20.776597 2021] [wsgi:error] [pid 49387:tid 139718659376896] [remote 188.147.38.41:61509]     apps.populate(settings.INSTALLED_APPS)
[Tue Jan 05 17:43:20.776634 2021] [wsgi:error] [pid 49387:tid 139718659376896] [remote 188.147.38.41:61509]   File "/usr/local/lib/python3.6/site-packages/django/apps/registry.py", line 83, in populate
[Tue Jan 05 17:43:20.776640 2021] [wsgi:error] [pid 49387:tid 139718659376896] [remote 188.147.38.41:61509]     raise RuntimeError("populate() isn't reentrant")
[Tue Jan 05 17:43:20.776666 2021] [wsgi:error] [pid 49387:tid 139718659376896] [remote 188.147.38.41:61509] RuntimeError: populate() isn't reentrant
[Tue Jan 05 17:43:21.408444 2021] [wsgi:error] [pid 49387:tid 139718667769600] [remote 188.147.38.41:61678] mod_wsgi (pid=49387): Failed to exec Python script file '/home/g11.labagh.pl/project/wsgi.py'.
[Tue Jan 05 17:43:21.408555 2021] [wsgi:error] [pid 49387:tid 139718667769600] [remote 188.147.38.41:61678] mod_wsgi (pid=49387): Exception occurred processing WSGI script '/home/g11.labagh.pl/project/wsgi.py'.
[Tue Jan 05 17:43:21.408876 2021] [wsgi:error] [pid 49387:tid 139718667769600] [remote 188.147.38.41:61678] Traceback (most recent call last):
[Tue Jan 05 17:43:21.408949 2021] [wsgi:error] [pid 49387:tid 139718667769600] [remote 188.147.38.41:61678]   File "/home/g11.labagh.pl/project/wsgi.py", line 16, in <module>
[Tue Jan 05 17:43:21.408961 2021] [wsgi:error] [pid 49387:tid 139718667769600] [remote 188.147.38.41:61678]     application = get_wsgi_application()
[Tue Jan 05 17:43:21.408979 2021] [wsgi:error] [pid 49387:tid 139718667769600] [remote 188.147.38.41:61678]   File "/usr/local/lib/python3.6/site-packages/django/core/wsgi.py", line 12, in get_wsgi_application
[Tue Jan 05 17:43:21.408990 2021] [wsgi:error] [pid 49387:tid 139718667769600] [remote 188.147.38.41:61678]     django.setup(set_prefix=False)
[Tue Jan 05 17:43:21.409004 2021] [wsgi:error] [pid 49387:tid 139718667769600] [remote 188.147.38.41:61678]   File "/usr/local/lib/python3.6/site-packages/django/__init__.py", line 24, in setup
[Tue Jan 05 17:43:21.409014 2021] [wsgi:error] [pid 49387:tid 139718667769600] [remote 188.147.38.41:61678]     apps.populate(settings.INSTALLED_APPS)
[Tue Jan 05 17:43:21.409027 2021] [wsgi:error] [pid 49387:tid 139718667769600] [remote 188.147.38.41:61678]   File "/usr/local/lib/python3.6/site-packages/django/apps/registry.py", line 83, in populate
[Tue Jan 05 17:43:21.409037 2021] [wsgi:error] [pid 49387:tid 139718667769600] [remote 188.147.38.41:61678]     raise RuntimeError("populate() isn't reentrant")
[Tue Jan 05 17:43:21.409069 2021] [wsgi:error] [pid 49387:tid 139718667769600] [remote 188.147.38.41:61678] RuntimeError: populate() isn't reentrant
[Tue Jan 05 17:43:22.099188 2021] [wsgi:error] [pid 49387:tid 139718659376896] [remote 188.147.38.41:61455] mod_wsgi (pid=49387): Failed to exec Python script file '/home/g11.labagh.pl/project/wsgi.py'.
[Tue Jan 05 17:43:22.099301 2021] [wsgi:error] [pid 49387:tid 139718659376896] [remote 188.147.38.41:61455] mod_wsgi (pid=49387): Exception occurred processing WSGI script '/home/g11.labagh.pl/project/wsgi.py'.
[Tue Jan 05 17:43:22.099551 2021] [wsgi:error] [pid 49387:tid 139718659376896] [remote 188.147.38.41:61455] Traceback (most recent call last):
[Tue Jan 05 17:43:22.099621 2021] [wsgi:error] [pid 49387:tid 139718659376896] [remote 188.147.38.41:61455]   File "/home/g11.labagh.pl/project/wsgi.py", line 16, in <module>
[Tue Jan 05 17:43:22.099633 2021] [wsgi:error] [pid 49387:tid 139718659376896] [remote 188.147.38.41:61455]     application = get_wsgi_application()
[Tue Jan 05 17:43:22.099650 2021] [wsgi:error] [pid 49387:tid 139718659376896] [remote 188.147.38.41:61455]   File "/usr/local/lib/python3.6/site-packages/django/core/wsgi.py", line 12, in get_wsgi_application
[Tue Jan 05 17:43:22.099660 2021] [wsgi:error] [pid 49387:tid 139718659376896] [remote 188.147.38.41:61455]     django.setup(set_prefix=False)
[Tue Jan 05 17:43:22.099674 2021] [wsgi:error] [pid 49387:tid 139718659376896] [remote 188.147.38.41:61455]   File "/usr/local/lib/python3.6/site-packages/django/__init__.py", line 24, in setup
[Tue Jan 05 17:43:22.099684 2021] [wsgi:error] [pid 49387:tid 139718659376896] [remote 188.147.38.41:61455]     apps.populate(settings.INSTALLED_APPS)
[Tue Jan 05 17:43:22.099726 2021] [wsgi:error] [pid 49387:tid 139718659376896] [remote 188.147.38.41:61455]   File "/usr/local/lib/python3.6/site-packages/django/apps/registry.py", line 83, in populate
[Tue Jan 05 17:43:22.099737 2021] [wsgi:error] [pid 49387:tid 139718659376896] [remote 188.147.38.41:61455]     raise RuntimeError("populate() isn't reentrant")
[Tue Jan 05 17:43:22.099797 2021] [wsgi:error] [pid 49387:tid 139718659376896] [remote 188.147.38.41:61455] RuntimeError: populate() isn't reentrant
[Tue Jan 05 17:44:42.325613 2021] [wsgi:error] [pid 49387:tid 139718667769600] [remote 188.147.38.41:27977] mod_wsgi (pid=49387): Failed to exec Python script file '/home/g11.labagh.pl/project/wsgi.py'.
[Tue Jan 05 17:44:42.325860 2021] [wsgi:error] [pid 49387:tid 139718667769600] [remote 188.147.38.41:27977] mod_wsgi (pid=49387): Exception occurred processing WSGI script '/home/g11.labagh.pl/project/wsgi.py'.
[Tue Jan 05 17:44:42.326347 2021] [wsgi:error] [pid 49387:tid 139718667769600] [remote 188.147.38.41:27977] Traceback (most recent call last):
[Tue Jan 05 17:44:42.326429 2021] [wsgi:error] [pid 49387:tid 139718667769600] [remote 188.147.38.41:27977]   File "/home/g11.labagh.pl/project/wsgi.py", line 16, in <module>
[Tue Jan 05 17:44:42.326442 2021] [wsgi:error] [pid 49387:tid 139718667769600] [remote 188.147.38.41:27977]     application = get_wsgi_application()
[Tue Jan 05 17:44:42.326466 2021] [wsgi:error] [pid 49387:tid 139718667769600] [remote 188.147.38.41:27977]   File "/usr/local/lib/python3.6/site-packages/django/core/wsgi.py", line 12, in get_wsgi_application
[Tue Jan 05 17:44:42.326478 2021] [wsgi:error] [pid 49387:tid 139718667769600] [remote 188.147.38.41:27977]     django.setup(set_prefix=False)
[Tue Jan 05 17:44:42.326493 2021] [wsgi:error] [pid 49387:tid 139718667769600] [remote 188.147.38.41:27977]   File "/usr/local/lib/python3.6/site-packages/django/__init__.py", line 24, in setup
[Tue Jan 05 17:44:42.326505 2021] [wsgi:error] [pid 49387:tid 139718667769600] [remote 188.147.38.41:27977]     apps.populate(settings.INSTALLED_APPS)
[Tue Jan 05 17:44:42.326519 2021] [wsgi:error] [pid 49387:tid 139718667769600] [remote 188.147.38.41:27977]   File "/usr/local/lib/python3.6/site-packages/django/apps/registry.py", line 83, in populate
[Tue Jan 05 17:44:42.326530 2021] [wsgi:error] [pid 49387:tid 139718667769600] [remote 188.147.38.41:27977]     raise RuntimeError("populate() isn't reentrant")
[Tue Jan 05 17:44:42.326574 2021] [wsgi:error] [pid 49387:tid 139718667769600] [remote 188.147.38.41:27977] RuntimeError: populate() isn't reentrant
[Tue Jan 05 17:44:51.266411 2021] [wsgi:error] [pid 49387:tid 139718659376896] [remote 188.147.38.41:28118] mod_wsgi (pid=49387): Failed to exec Python script file '/home/g11.labagh.pl/project/wsgi.py'.
[Tue Jan 05 17:44:51.266508 2021] [wsgi:error] [pid 49387:tid 139718659376896] [remote 188.147.38.41:28118] mod_wsgi (pid=49387): Exception occurred processing WSGI script '/home/g11.labagh.pl/project/wsgi.py'.
[Tue Jan 05 17:44:51.266719 2021] [wsgi:error] [pid 49387:tid 139718659376896] [remote 188.147.38.41:28118] Traceback (most recent call last):
[Tue Jan 05 17:44:51.266822 2021] [wsgi:error] [pid 49387:tid 139718659376896] [remote 188.147.38.41:28118]   File "/home/g11.labagh.pl/project/wsgi.py", line 16, in <module>
[Tue Jan 05 17:44:51.266834 2021] [wsgi:error] [pid 49387:tid 139718659376896] [remote 188.147.38.41:28118]     application = get_wsgi_application()
[Tue Jan 05 17:44:51.266847 2021] [wsgi:error] [pid 49387:tid 139718659376896] [remote 188.147.38.41:28118]   File "/usr/local/lib/python3.6/site-packages/django/core/wsgi.py", line 12, in get_wsgi_application
[Tue Jan 05 17:44:51.266856 2021] [wsgi:error] [pid 49387:tid 139718659376896] [remote 188.147.38.41:28118]     django.setup(set_prefix=False)
[Tue Jan 05 17:44:51.266867 2021] [wsgi:error] [pid 49387:tid 139718659376896] [remote 188.147.38.41:28118]   File "/usr/local/lib/python3.6/site-packages/django/__init__.py", line 24, in setup
[Tue Jan 05 17:44:51.266895 2021] [wsgi:error] [pid 49387:tid 139718659376896] [remote 188.147.38.41:28118]     apps.populate(settings.INSTALLED_APPS)
[Tue Jan 05 17:44:51.266906 2021] [wsgi:error] [pid 49387:tid 139718659376896] [remote 188.147.38.41:28118]   File "/usr/local/lib/python3.6/site-packages/django/apps/registry.py", line 83, in populate
[Tue Jan 05 17:44:51.266913 2021] [wsgi:error] [pid 49387:tid 139718659376896] [remote 188.147.38.41:28118]     raise RuntimeError("populate() isn't reentrant")
[Tue Jan 05 17:44:51.266945 2021] [wsgi:error] [pid 49387:tid 139718659376896] [remote 188.147.38.41:28118] RuntimeError: populate() isn't reentrant
[Tue Jan 05 17:50:10.361026 2021] [wsgi:error] [pid 49387:tid 139718667769600] [remote 89.64.42.253:30248] mod_wsgi (pid=49387): Failed to exec Python script file '/home/g11.labagh.pl/project/wsgi.py'.
[Tue Jan 05 17:50:10.361321 2021] [wsgi:error] [pid 49387:tid 139718667769600] [remote 89.64.42.253:30248] mod_wsgi (pid=49387): Exception occurred processing WSGI script '/home/g11.labagh.pl/project/wsgi.py'.
[Tue Jan 05 17:50:10.362051 2021] [wsgi:error] [pid 49387:tid 139718667769600] [remote 89.64.42.253:30248] Traceback (most recent call last):
[Tue Jan 05 17:50:10.362169 2021] [wsgi:error] [pid 49387:tid 139718667769600] [remote 89.64.42.253:30248]   File "/home/g11.labagh.pl/project/wsgi.py", line 16, in <module>
[Tue Jan 05 17:50:10.362184 2021] [wsgi:error] [pid 49387:tid 139718667769600] [remote 89.64.42.253:30248]     application = get_wsgi_application()
[Tue Jan 05 17:50:10.362215 2021] [wsgi:error] [pid 49387:tid 139718667769600] [remote 89.64.42.253:30248]   File "/usr/local/lib/python3.6/site-packages/django/core/wsgi.py", line 12, in get_wsgi_application
[Tue Jan 05 17:50:10.362227 2021] [wsgi:error] [pid 49387:tid 139718667769600] [remote 89.64.42.253:30248]     django.setup(set_prefix=False)
[Tue Jan 05 17:50:10.362243 2021] [wsgi:error] [pid 49387:tid 139718667769600] [remote 89.64.42.253:30248]   File "/usr/local/lib/python3.6/site-packages/django/__init__.py", line 24, in setup
[Tue Jan 05 17:50:10.362254 2021] [wsgi:error] [pid 49387:tid 139718667769600] [remote 89.64.42.253:30248]     apps.populate(settings.INSTALLED_APPS)
[Tue Jan 05 17:50:10.362268 2021] [wsgi:error] [pid 49387:tid 139718667769600] [remote 89.64.42.253:30248]   File "/usr/local/lib/python3.6/site-packages/django/apps/registry.py", line 83, in populate
[Tue Jan 05 17:50:10.362280 2021] [wsgi:error] [pid 49387:tid 139718667769600] [remote 89.64.42.253:30248]     raise RuntimeError("populate() isn't reentrant")
[Tue Jan 05 17:50:10.362328 2021] [wsgi:error] [pid 49387:tid 139718667769600] [remote 89.64.42.253:30248] RuntimeError: populate() isn't reentrant
[Tue Jan 05 17:50:10.677334 2021] [wsgi:error] [pid 49387:tid 139718659376896] [remote 89.64.42.253:30245] mod_wsgi (pid=49387): Failed to exec Python script file '/home/g11.labagh.pl/project/wsgi.py'.
[Tue Jan 05 17:50:10.677436 2021] [wsgi:error] [pid 49387:tid 139718659376896] [remote 89.64.42.253:30245] mod_wsgi (pid=49387): Exception occurred processing WSGI script '/home/g11.labagh.pl/project/wsgi.py'.
[Tue Jan 05 17:50:10.677657 2021] [wsgi:error] [pid 49387:tid 139718659376896] [remote 89.64.42.253:30245] Traceback (most recent call last):
[Tue Jan 05 17:50:10.677736 2021] [wsgi:error] [pid 49387:tid 139718659376896] [remote 89.64.42.253:30245]   File "/home/g11.labagh.pl/project/wsgi.py", line 16, in <module>
[Tue Jan 05 17:50:10.677749 2021] [wsgi:error] [pid 49387:tid 139718659376896] [remote 89.64.42.253:30245]     application = get_wsgi_application()
[Tue Jan 05 17:50:10.677790 2021] [wsgi:error] [pid 49387:tid 139718659376896] [remote 89.64.42.253:30245]   File "/usr/local/lib/python3.6/site-packages/django/core/wsgi.py", line 12, in get_wsgi_application
[Tue Jan 05 17:50:10.677802 2021] [wsgi:error] [pid 49387:tid 139718659376896] [remote 89.64.42.253:30245]     django.setup(set_prefix=False)
[Tue Jan 05 17:50:10.677818 2021] [wsgi:error] [pid 49387:tid 139718659376896] [remote 89.64.42.253:30245]   File "/usr/local/lib/python3.6/site-packages/django/__init__.py", line 24, in setup
[Tue Jan 05 17:50:10.677867 2021] [wsgi:error] [pid 49387:tid 139718659376896] [remote 89.64.42.253:30245]     apps.populate(settings.INSTALLED_APPS)
[Tue Jan 05 17:50:10.677883 2021] [wsgi:error] [pid 49387:tid 139718659376896] [remote 89.64.42.253:30245]   File "/usr/local/lib/python3.6/site-packages/django/apps/registry.py", line 83, in populate
[Tue Jan 05 17:50:10.677893 2021] [wsgi:error] [pid 49387:tid 139718659376896] [remote 89.64.42.253:30245]     raise RuntimeError("populate() isn't reentrant")
[Tue Jan 05 17:50:10.677923 2021] [wsgi:error] [pid 49387:tid 139718659376896] [remote 89.64.42.253:30245] RuntimeError: populate() isn't reentrant
[Tue Jan 05 17:53:47.312949 2021] [wsgi:error] [pid 49387:tid 139718667769600] [remote 89.64.42.253:30322] mod_wsgi (pid=49387): Failed to exec Python script file '/home/g11.labagh.pl/project/wsgi.py'.
[Tue Jan 05 17:53:47.313125 2021] [wsgi:error] [pid 49387:tid 139718667769600] [remote 89.64.42.253:30322] mod_wsgi (pid=49387): Exception occurred processing WSGI script '/home/g11.labagh.pl/project/wsgi.py'.
[Tue Jan 05 17:53:47.313453 2021] [wsgi:error] [pid 49387:tid 139718667769600] [remote 89.64.42.253:30322] Traceback (most recent call last):
[Tue Jan 05 17:53:47.313502 2021] [wsgi:error] [pid 49387:tid 139718667769600] [remote 89.64.42.253:30322]   File "/home/g11.labagh.pl/project/wsgi.py", line 16, in <module>
[Tue Jan 05 17:53:47.313509 2021] [wsgi:error] [pid 49387:tid 139718667769600] [remote 89.64.42.253:30322]     application = get_wsgi_application()
[Tue Jan 05 17:53:47.313521 2021] [wsgi:error] [pid 49387:tid 139718667769600] [remote 89.64.42.253:30322]   File "/usr/local/lib/python3.6/site-packages/django/core/wsgi.py", line 12, in get_wsgi_application
[Tue Jan 05 17:53:47.313526 2021] [wsgi:error] [pid 49387:tid 139718667769600] [remote 89.64.42.253:30322]     django.setup(set_prefix=False)
[Tue Jan 05 17:53:47.313534 2021] [wsgi:error] [pid 49387:tid 139718667769600] [remote 89.64.42.253:30322]   File "/usr/local/lib/python3.6/site-packages/django/__init__.py", line 24, in setup
[Tue Jan 05 17:53:47.313539 2021] [wsgi:error] [pid 49387:tid 139718667769600] [remote 89.64.42.253:30322]     apps.populate(settings.INSTALLED_APPS)
[Tue Jan 05 17:53:47.313546 2021] [wsgi:error] [pid 49387:tid 139718667769600] [remote 89.64.42.253:30322]   File "/usr/local/lib/python3.6/site-packages/django/apps/registry.py", line 83, in populate
[Tue Jan 05 17:53:47.313551 2021] [wsgi:error] [pid 49387:tid 139718667769600] [remote 89.64.42.253:30322]     raise RuntimeError("populate() isn't reentrant")
[Tue Jan 05 17:53:47.313575 2021] [wsgi:error] [pid 49387:tid 139718667769600] [remote 89.64.42.253:30322] RuntimeError: populate() isn't reentrant
[Tue Jan 05 17:53:47.530255 2021] [wsgi:error] [pid 49387:tid 139718659376896] [remote 89.64.42.253:30225] mod_wsgi (pid=49387): Failed to exec Python script file '/home/g11.labagh.pl/project/wsgi.py'.
[Tue Jan 05 17:53:47.530364 2021] [wsgi:error] [pid 49387:tid 139718659376896] [remote 89.64.42.253:30225] mod_wsgi (pid=49387): Exception occurred processing WSGI script '/home/g11.labagh.pl/project/wsgi.py'.
[Tue Jan 05 17:53:47.530581 2021] [wsgi:error] [pid 49387:tid 139718659376896] [remote 89.64.42.253:30225] Traceback (most recent call last):
[Tue Jan 05 17:53:47.530659 2021] [wsgi:error] [pid 49387:tid 139718659376896] [remote 89.64.42.253:30225]   File "/home/g11.labagh.pl/project/wsgi.py", line 16, in <module>
[Tue Jan 05 17:53:47.530672 2021] [wsgi:error] [pid 49387:tid 139718659376896] [remote 89.64.42.253:30225]     application = get_wsgi_application()
[Tue Jan 05 17:53:47.530689 2021] [wsgi:error] [pid 49387:tid 139718659376896] [remote 89.64.42.253:30225]   File "/usr/local/lib/python3.6/site-packages/django/core/wsgi.py", line 12, in get_wsgi_application
[Tue Jan 05 17:53:47.530700 2021] [wsgi:error] [pid 49387:tid 139718659376896] [remote 89.64.42.253:30225]     django.setup(set_prefix=False)
[Tue Jan 05 17:53:47.530756 2021] [wsgi:error] [pid 49387:tid 139718659376896] [remote 89.64.42.253:30225]   File "/usr/local/lib/python3.6/site-packages/django/__init__.py", line 24, in setup
[Tue Jan 05 17:53:47.530838 2021] [wsgi:error] [pid 49387:tid 139718659376896] [remote 89.64.42.253:30225]     apps.populate(settings.INSTALLED_APPS)
[Tue Jan 05 17:53:47.530856 2021] [wsgi:error] [pid 49387:tid 139718659376896] [remote 89.64.42.253:30225]   File "/usr/local/lib/python3.6/site-packages/django/apps/registry.py", line 83, in populate
[Tue Jan 05 17:53:47.530866 2021] [wsgi:error] [pid 49387:tid 139718659376896] [remote 89.64.42.253:30225]     raise RuntimeError("populate() isn't reentrant")
[Tue Jan 05 17:53:47.530898 2021] [wsgi:error] [pid 49387:tid 139718659376896] [remote 89.64.42.253:30225] RuntimeError: populate() isn't reentrant
[Tue Jan 05 17:58:11.470504 2021] [wsgi:error] [pid 49387:tid 139718667769600] [remote 89.64.42.253:30275] mod_wsgi (pid=49387): Failed to exec Python script file '/home/g11.labagh.pl/project/wsgi.py'.
[Tue Jan 05 17:58:11.470723 2021] [wsgi:error] [pid 49387:tid 139718667769600] [remote 89.64.42.253:30275] mod_wsgi (pid=49387): Exception occurred processing WSGI script '/home/g11.labagh.pl/project/wsgi.py'.
[Tue Jan 05 17:58:11.471224 2021] [wsgi:error] [pid 49387:tid 139718667769600] [remote 89.64.42.253:30275] Traceback (most recent call last):
[Tue Jan 05 17:58:11.471314 2021] [wsgi:error] [pid 49387:tid 139718667769600] [remote 89.64.42.253:30275]   File "/home/g11.labagh.pl/project/wsgi.py", line 16, in <module>
[Tue Jan 05 17:58:11.471325 2021] [wsgi:error] [pid 49387:tid 139718667769600] [remote 89.64.42.253:30275]     application = get_wsgi_application()
[Tue Jan 05 17:58:11.471347 2021] [wsgi:error] [pid 49387:tid 139718667769600] [remote 89.64.42.253:30275]   File "/usr/local/lib/python3.6/site-packages/django/core/wsgi.py", line 12, in get_wsgi_application
[Tue Jan 05 17:58:11.471356 2021] [wsgi:error] [pid 49387:tid 139718667769600] [remote 89.64.42.253:30275]     django.setup(set_prefix=False)
[Tue Jan 05 17:58:11.471367 2021] [wsgi:error] [pid 49387:tid 139718667769600] [remote 89.64.42.253:30275]   File "/usr/local/lib/python3.6/site-packages/django/__init__.py", line 24, in setup
[Tue Jan 05 17:58:11.471375 2021] [wsgi:error] [pid 49387:tid 139718667769600] [remote 89.64.42.253:30275]     apps.populate(settings.INSTALLED_APPS)
[Tue Jan 05 17:58:11.471386 2021] [wsgi:error] [pid 49387:tid 139718667769600] [remote 89.64.42.253:30275]   File "/usr/local/lib/python3.6/site-packages/django/apps/registry.py", line 83, in populate
[Tue Jan 05 17:58:11.471394 2021] [wsgi:error] [pid 49387:tid 139718667769600] [remote 89.64.42.253:30275]     raise RuntimeError("populate() isn't reentrant")
[Tue Jan 05 17:58:11.471427 2021] [wsgi:error] [pid 49387:tid 139718667769600] [remote 89.64.42.253:30275] RuntimeError: populate() isn't reentrant
[Tue Jan 05 17:58:14.752535 2021] [wsgi:error] [pid 49387:tid 139718659376896] [remote 89.64.42.253:30274] mod_wsgi (pid=49387): Failed to exec Python script file '/home/g11.labagh.pl/project/wsgi.py'.
[Tue Jan 05 17:58:14.752651 2021] [wsgi:error] [pid 49387:tid 139718659376896] [remote 89.64.42.253:30274] mod_wsgi (pid=49387): Exception occurred processing WSGI script '/home/g11.labagh.pl/project/wsgi.py'.
[Tue Jan 05 17:58:14.752916 2021] [wsgi:error] [pid 49387:tid 139718659376896] [remote 89.64.42.253:30274] Traceback (most recent call last):
[Tue Jan 05 17:58:14.753033 2021] [wsgi:error] [pid 49387:tid 139718659376896] [remote 89.64.42.253:30274]   File "/home/g11.labagh.pl/project/wsgi.py", line 16, in <module>
[Tue Jan 05 17:58:14.753052 2021] [wsgi:error] [pid 49387:tid 139718659376896] [remote 89.64.42.253:30274]     application = get_wsgi_application()
[Tue Jan 05 17:58:14.753071 2021] [wsgi:error] [pid 49387:tid 139718659376896] [remote 89.64.42.253:30274]   File "/usr/local/lib/python3.6/site-packages/django/core/wsgi.py", line 12, in get_wsgi_application
[Tue Jan 05 17:58:14.753082 2021] [wsgi:error] [pid 49387:tid 139718659376896] [remote 89.64.42.253:30274]     django.setup(set_prefix=False)
[Tue Jan 05 17:58:14.753142 2021] [wsgi:error] [pid 49387:tid 139718659376896] [remote 89.64.42.253:30274]   File "/usr/local/lib/python3.6/site-packages/django/__init__.py", line 24, in setup
[Tue Jan 05 17:58:14.753153 2021] [wsgi:error] [pid 49387:tid 139718659376896] [remote 89.64.42.253:30274]     apps.populate(settings.INSTALLED_APPS)
[Tue Jan 05 17:58:14.753166 2021] [wsgi:error] [pid 49387:tid 139718659376896] [remote 89.64.42.253:30274]   File "/usr/local/lib/python3.6/site-packages/django/apps/registry.py", line 83, in populate
[Tue Jan 05 17:58:14.753176 2021] [wsgi:error] [pid 49387:tid 139718659376896] [remote 89.64.42.253:30274]     raise RuntimeError("populate() isn't reentrant")
[Tue Jan 05 17:58:14.753207 2021] [wsgi:error] [pid 49387:tid 139718659376896] [remote 89.64.42.253:30274] RuntimeError: populate() isn't reentrant
[Tue Jan 05 17:58:15.755012 2021] [wsgi:error] [pid 49387:tid 139718667769600] [remote 89.64.42.253:30201] mod_wsgi (pid=49387): Failed to exec Python script file '/home/g11.labagh.pl/project/wsgi.py'.
[Tue Jan 05 17:58:15.755115 2021] [wsgi:error] [pid 49387:tid 139718667769600] [remote 89.64.42.253:30201] mod_wsgi (pid=49387): Exception occurred processing WSGI script '/home/g11.labagh.pl/project/wsgi.py'.
[Tue Jan 05 17:58:15.755371 2021] [wsgi:error] [pid 49387:tid 139718667769600] [remote 89.64.42.253:30201] Traceback (most recent call last):
[Tue Jan 05 17:58:15.755438 2021] [wsgi:error] [pid 49387:tid 139718667769600] [remote 89.64.42.253:30201]   File "/home/g11.labagh.pl/project/wsgi.py", line 16, in <module>
[Tue Jan 05 17:58:15.755451 2021] [wsgi:error] [pid 49387:tid 139718667769600] [remote 89.64.42.253:30201]     application = get_wsgi_application()
[Tue Jan 05 17:58:15.755468 2021] [wsgi:error] [pid 49387:tid 139718667769600] [remote 89.64.42.253:30201]   File "/usr/local/lib/python3.6/site-packages/django/core/wsgi.py", line 12, in get_wsgi_application
[Tue Jan 05 17:58:15.755480 2021] [wsgi:error] [pid 49387:tid 139718667769600] [remote 89.64.42.253:30201]     django.setup(set_prefix=False)
[Tue Jan 05 17:58:15.755494 2021] [wsgi:error] [pid 49387:tid 139718667769600] [remote 89.64.42.253:30201]   File "/usr/local/lib/python3.6/site-packages/django/__init__.py", line 24, in setup
[Tue Jan 05 17:58:15.755505 2021] [wsgi:error] [pid 49387:tid 139718667769600] [remote 89.64.42.253:30201]     apps.populate(settings.INSTALLED_APPS)
[Tue Jan 05 17:58:15.755520 2021] [wsgi:error] [pid 49387:tid 139718667769600] [remote 89.64.42.253:30201]   File "/usr/local/lib/python3.6/site-packages/django/apps/registry.py", line 83, in populate
[Tue Jan 05 17:58:15.755531 2021] [wsgi:error] [pid 49387:tid 139718667769600] [remote 89.64.42.253:30201]     raise RuntimeError("populate() isn't reentrant")
[Tue Jan 05 17:58:15.755561 2021] [wsgi:error] [pid 49387:tid 139718667769600] [remote 89.64.42.253:30201] RuntimeError: populate() isn't reentrant
[Tue Jan 05 17:58:42.802702 2021] [wsgi:error] [pid 49387:tid 139718659376896] [remote 188.147.38.41:61605] mod_wsgi (pid=49387): Failed to exec Python script file '/home/g11.labagh.pl/project/wsgi.py'.
[Tue Jan 05 17:58:42.803034 2021] [wsgi:error] [pid 49387:tid 139718659376896] [remote 188.147.38.41:61605] mod_wsgi (pid=49387): Exception occurred processing WSGI script '/home/g11.labagh.pl/project/wsgi.py'.
[Tue Jan 05 17:58:42.804223 2021] [wsgi:error] [pid 49387:tid 139718659376896] [remote 188.147.38.41:61605] Traceback (most recent call last):
[Tue Jan 05 17:58:42.804347 2021] [wsgi:error] [pid 49387:tid 139718659376896] [remote 188.147.38.41:61605]   File "/home/g11.labagh.pl/project/wsgi.py", line 16, in <module>
[Tue Jan 05 17:58:42.804366 2021] [wsgi:error] [pid 49387:tid 139718659376896] [remote 188.147.38.41:61605]     application = get_wsgi_application()
[Tue Jan 05 17:58:42.804387 2021] [wsgi:error] [pid 49387:tid 139718659376896] [remote 188.147.38.41:61605]   File "/usr/local/lib/python3.6/site-packages/django/core/wsgi.py", line 12, in get_wsgi_application
[Tue Jan 05 17:58:42.804403 2021] [wsgi:error] [pid 49387:tid 139718659376896] [remote 188.147.38.41:61605]     django.setup(set_prefix=False)
[Tue Jan 05 17:58:42.804465 2021] [wsgi:error] [pid 49387:tid 139718659376896] [remote 188.147.38.41:61605]   File "/usr/local/lib/python3.6/site-packages/django/__init__.py", line 24, in setup
[Tue Jan 05 17:58:42.804480 2021] [wsgi:error] [pid 49387:tid 139718659376896] [remote 188.147.38.41:61605]     apps.populate(settings.INSTALLED_APPS)
[Tue Jan 05 17:58:42.804502 2021] [wsgi:error] [pid 49387:tid 139718659376896] [remote 188.147.38.41:61605]   File "/usr/local/lib/python3.6/site-packages/django/apps/registry.py", line 83, in populate
[Tue Jan 05 17:58:42.804541 2021] [wsgi:error] [pid 49387:tid 139718659376896] [remote 188.147.38.41:61605]     raise RuntimeError("populate() isn't reentrant")
[Tue Jan 05 17:58:42.804625 2021] [wsgi:error] [pid 49387:tid 139718659376896] [remote 188.147.38.41:61605] RuntimeError: populate() isn't reentrant
